model
name = -138-wall_wdoor_ext_brick_broken
size = 31 31 15
scale = 0.05
origin = -y
material type = toon, lighting = smooth, deform = 1 1 
  colors = A:#4B4B4B B:#353535 C:#555 D:#5A5A5A
voxels
CBDABDCDCADDCADCDABDCDDDBDCCBAC ADCCDBDABACDAABBADBBADAAADBADAB BADCCBDDCACCDABCBAACAADCABBDBCB DBCCADDBCDBAAACDAABDDBCDADCBCAB AADCADACBDDAADAADDDCBCCCCAAADDB CADCCDAACABBABBCDADDBCBDBCBACDC CDCDAADCBBCDBCCABABBBDAAABDBBBD DBCBDDAAADADCADBDAACBCDDDDCACBB ACBACDCACBABDAADCCBDBBAADBDBBCC BDBACACBBCCCCCBDADDBCDBCCCDDDAD DCACBADDABDDCBDDBACBDABCCCABBBA DBCBCDCDDCDDBBDAADDDDCCDCCCAACA DCBBACDDABBDABACBBAABCBCDDDDDDB DDBACCDCDADCDDCDDDADCCCBBCADCCC BCABBBBAADBCBBBAABDAABAADCAAABA ADABACACDCBCCCCBABBCCBAADABADAA ABBCBDDCDCBDDBBADCCDDBDCBBBDDDA AACACABCACBDABBDDABCADADCCBACAC DDCBACAAABBBBABCBCABADCDCCBABAD DDAABBCAABDAAADADBCCACADABBDBAB BADAACADDABAAADADBCCAADCBCACADA ACCBDDBAAADABBCDBABCBBDBCDADBBD ADCCBBABAAAACAADABDBCCACABAACAA AABCCAADCDDBCBACACCBCCCDDBBBBCB DBABCBCDADBDBDDDCABCBBCACBDBBAA ADCDBDADDDDBBBDABDABCCDCBCABABD DBBCBBCDACDCBBCDDBABCDDAADBDDDC CACBBCDDBCCDCCBCBBDACDCCBABCCCA ADABBBDCBBBABDDDABBDABDDDBBAAAC AACDCBCBAABADBAAADACBDAADCAACAD BCCBDCAACBBBBBDDCBCBDBDDCDDCCBD 
DCBDADBDDCABABDABDDDBBCBCCAADBC ACBBDDACDDCCDBDCDBCCBDDBBCDCDAB DAADABACDDDABCCDCDBDCDBBDCCBBCC DACCDCACAADDBAADDBADDDADDBBCAAB BACBBADBABBCCABBACBADACDCDABCAA CDDBCDBDCBADDDBDBACDBADAACDABAC BAABACBABDACACACCBBAACCDBADBCCC DBADDDCBDDDBBAAABAAAABDCBACDBBB BCCCBBABCCBBBAACCCDADCBCBADADDB CDBCDAAADBDDAADCADDCBDDCDBABBBC ACADCDAABBDDCCCABCADCDCBADABCAB CBABCCBDBCABABBBADDBACACDCBCBDC BBDDAABCACAAADCACAADACCACDDBCAC AACBDCACBCBBACCCCCBCDDDCCDACACC DDBDABDCDDCACABDBBACBACBBDCCBCB ACBBADBBDDABABDCABBADAABCBBADAC DBCDCCACDCABACBDCADABCCBBDBDCAC BCDADDDBCCCBBABCABACBCCACDDCBDC DADDDDABCACBDABDABAADCCDCCCBAAB AADDAADCDDCCCDCCBBADDACDBDDABDA DACCDADCABBCDBACDADDCACDDCCDAAD BABACBCCABDDAACABBDCBCDACCAADBA DAAABAADBBADDCBBBBDDDDCCDDBCABD BADBAADCBCBACCCDDABDBAAACBBACBB AABADDCCDCDBDCACAACACCCACADADDD DAAABADBAADBBACADAABADDDBDCADAA DBCBBACDDCCCBCDADBBBABDDACBCBCD BADCBABCBDCAAAACBABBBDDCACDADBA CBAACAAACBCAADDCAADCABBBDCBBBBB CACDBBCDCDADAABBCBCDDDDCBADABAC ACCABBCCDAADBBBDBCABCAADCDABCBA 
ABACCDCCADADBBCBBBDDABABABCDBCC BDBBAABCBCAABBABBADAAADADCDBCBA ABBDCBACBDDABDCDCDBCBDDADAAABCA DBBBBCBADABACADBCBDCDABADDCBCAC CDACCBBACCDABBBCDABDCCCDDABCBDD BABDCBDCACAAABDADDAADDDAAACDBAD DADDABCBABCDBABADCBCDABBACADBCA BBDABDBBCCABDADBCDBBDDBDABABCDA BCABABDAACCBADAADDDDACCACDABDBD CBCCCDDADCDADCDCBDCCDCCCCCAACBA CBDBDDCDADADBCACABAADACCCAADDCA DBCBAABBCABCBBADBCDACAABAAABADC DBCBBDCCBDCADBAACCBDACDBADDCACC ACCABACAAAABBACBABCBDACBAABCACD ADDAAACDBBDDADBDAACBCADABBAAACD DBCAAACDABADBABBAACABAABBACBBCC CAABBACABDDBBABDBDBABBCCBCDAAAB CBADBCDBBACBCDCDDBDBDBDBDDDACCC CDCAAACAACCDBACBBDDACBBADBBDBBD DDBBADDDCDBCBADBDAAAADACCBBABCC BBAABDABCBBCDADCDBBBDDACCAADBCD DCCABDBCDBCCDDCCBABDCCAAADCADAD CBDABCCBBADCCAABAADBCBBCDBAADDB BDDADCCAADACBBBDCCBCDACADCDCDCC DBBAABADDDABBDCDABCAAAABDCBBDAC DDCBCBCDDBACCAAAADCADBCBDDBACCD CCDBBCACADDDCADABBCDAAAACDBDDAB BABBCADABAABADCDCAADACBACBCCAAA BBADDDDCABADDDBDDBBBBACABBDCBAA DBCABABBBAACABBACDCCDBCCDBCCCAB DBCCACCDDBBCCBDADBADBBDCBDACBCC 
DCCDBDCBAAAAADBDCDAACACDBAAAABA BDADBBDCBCCDADCCCCDBDCACCCBABDB BBBCADCCACBBCBBCDCBABADCCBADCAD ABDBDDBCCABDAC---AABBBDBAACCAAD BBABAADCADBBDA---DAACCDBBDBBBCB BBBCBBADAAAABB---ABABDBCDABACDB BDCDABCBDCAADABCDCABBABDBCBBBDC BADBBADCCDDCAABCCCADDAABABCBADA AACDDBBBDAABACBCDCDCBAABBDBBBDC BDACADBDBBDABBABCB---BABDBBCBAC ACCBCBDBDDCAAABDCC---BBBCCCCACC BABBCDBCBBDBDABAAB---DCBDBBCCDC ADBADDDAADABACDAADDBAACACDBBCAC BBBAAADDCCBCCDDACCBBBCBDBDDAADA DADCBCDABDDBBAADACBDDDDAADADABD CDDACBADABCDCAACACACCACCBCBCCBA AABCAAABCDACAABAACABDBBBBCDACAB DCBADADCDADCBDBDBCBDDCBBBDBDDAD CBBBDABBAABDBBBDADDADDDCCAACAAC CCACCACDAAACDDDDAADACBDAACBDDBA DBBACABBCACAADDABABBBDDBDCCAABD CCCACDABAADDCBCDCDAAADBDDDDBBDA AADDCDABDBDCBBDBCCABBCAACCDBAAA ABDCBAACADABDDADABADDBDCCADADCA ADBBBDAACCBCBBCCCBBBDBCADDCDAAB DDABCDDBDACDBDABCDDCADDBDCDCBBD CDBDBBAACDDCDDCBBBBDDABBCAAADAC ADBBCCAACBDDBACCDDBDADBACDCADCB DDBBBDABAAAABAABDDDCBDDDABBCBDA BCADBBCCCDDDABCBDDABDDAAABADBCB DACABCABCDDCBDBAACAABBDDBDDBDBC 
CCADDACBDBCBCACBBCBCBACBDACACDB DACABDCBAADBBB----BBCDCCABCBCAD CBDAADDBABBDDB----BBBDDDCDCBDCC BADCDDBBDBBCD-----CADADDDDADDCA CBDBBCACABCBA-----ACBAABDCADBDC ABCCADACABCDC-----ADDDCBBDDDAAD BDBCAABCCAADCC---DBDBCBACCDDACD DCDCDBACBDDCBAAABCACCABACDACABB BCBDCCDACCBCCDCDAD---ADCCAABAAA CBBCAACB---DDDBAA-----ABACCADCA CDDCDCDD---CBADBB-----DDCDBCDCB CCDAADAC---DDABBB-----CDDCBACBC AACDCBABABDCBCBACD----BCAABACCA ACBBCDBCDCDAACBADADDBADADCBCBCA DDBBCCADABCCDADBCCCCDCBCCCDCCCC DCCCABBDCADBAADACDCADDACDADAABB DDADDCBACDCBBBCCCACCDACBDCBDBCA CCBBBDDCCBBACBAAAAACCDADDBBDDDA CBCACAACAAACCDBDADBBDDCADABBBBB DBCDCADCBDCCDCCADDCABABAABDDDBA DDAACDACDBDDADDDDADBCDBBCDDADDD ACAADDCCCADDCCBCDABACCDBDDBCABC BACACACDDDABADABDCCDBCDBCCADCCB DADCBDCDCDADAACAABDCCCDDAADDBCD CDDDDBABABBACADABBDAAAABAABBACD DBABBCACDBDBBDBCBCCCADCCCABBACA BDCCBCBDCCBAADBCCBCDCBCBABBBAAA CBAADDCADABBADADABABAADAADBBBDC DBCABCBDCDABACCBCDBAACACCADABCD CDBBABCCCAAACCABBBADACCBBCACACB BCCDDBDCDDDBBCBCDCDBDBBABDCADDD 
DBBAADCBAAADDD----AADDCBCCCDACB AABAACCCDDBDD------ABDDDDADBCAD BCBCBAADCDCAB------BCCBBADACAAC BBABBBAACDADC------BBAABDABCACD CCCDDBABCC-DD-----BACDBBCDCDCAA DAACCCDACDBBB-----ADDADADDCADDC AADAADCACDA-DD---AAACABABADDDDA DCACBCDACCBBCBDAACCBDAABCABDAAB CBACDCBB---CCCDBAC---AABABBBCAC BBBBDCA-----DADAC-----ACAADCACB CADCDBD-----CCBAA------DADADBBD DCBBBBC-----ACCBC------AAAAABAC BBAADCB----AAACBB------CCBCCDCC ACCDCDBBADBCABACDD----DBBDDACAC CAAADAACCBADDADABBABCCABADDCCBD BBDBBDBBADDABBCCDACABDDABABDBBA BBCADDBBDDABDCCDCADCBADCCCCCBDA DCCCADBCBCDBBCAADADCCCDDCABAABB DBCBBAACBBBAACDDDBACAADADAABCCB BADAABDBBCDAABCACBABCCBCCCBDCDD BBDBBBABBDCBDDBBA---CBBBDAABBBD BBCACCCBDAADACBCB---CBAADAACDDC CDACBCCABCADCCBDA---CACCCBADBCB DDBBDCCABCCACCCDD---BADBBCBCBBC ADCDBCAAABCDABDAC---ACDCDBCCCAA CDDCADCCCAABBDCCDDCDABBCABDDDAD CBCDBADAADAACBDAADDCDADAADCDCDA CBADCBCBDCCDADDDCACBBDBCCBCADCA AAABDCDACDCCAAADACCCDADCCBDCDAC BAACDCCDDDBAAADCBCABACACCCDDDCC CBAABACAADDDBCDAAACCDADCCBADADC 
ACAAAABDABAD------BCDDCCDBDDCBC CCADAACACCCDD------C-ABBAADAACB ADDBADBBDAAAA--------BCC---CACC ABDCADBDD--CB------ADABC---CDCC CDDCDCDBB---C-----DACCAC---BBBD BBADAACADA--------ABCBDCDDCC--- CCCBAACCDD---B---AB-BBADCBDC--- CDCCBACCDDA-BCAA-DA-BDACBBBB--- AABAACDC----CABA-------BCAADBDA CBBDCBD------BCA-------CBDBAADA CADCDC-------BA--------CCABCAAD DCBCCD----------B------BCCBDADD BAAAAB-----BC--DD------CAAACAAC BDDDCCD---DAD--BD-----ADBAABACC DCADCBDBCBCCDBBCB-ACBBCAACCCDDC BBDBABBBC--CA-ABDCBBACDACCBBAAC DDBBDDCCBA-CD-D-BDCDCAACCABACBD BCAAADCDCCBDADB-ABDCBACCDDDDABB CACCBBABAAADACD-BDABCCDCDACBCCB ACAACCBDBDDADBB-A---BBCAACABCBC ADDDBBCDBCCBAABD-----DBCCBDBBAC BBADADADBCDBDABA-----CCAADBBDDD BAADCCABCAAAAAAB-----BBACCACDDD ACDADACCDCACCAAB-----BBBBDCABCC ADACDDDCABDDBCAA-----DABDCCBABB CBAAADADBCDDAABC-----CCADABADDB BAABBCCAABBDCACC-----BDABBBBBDB DACACABBAACADDCD---BABACDACAACD AACADCAABBDCBACB---DDDCCDDADBCC ACABBCAABBDDBDBA---BADDBBACDCCC ACCAABADAACADBBC---ADCDDCBBBAAB 
BCB---CBA------------B---DBCDAD CDC---ACD------------D-----ABDC DBB---CBC------------A--------- BAACBADAC------------A--------- CBBAABCDD------------DA-------- CDBDCBCAC---------------------- DDCBADAAB--------------CCCA---- BBCBBAACD--------------BCCD---- BDACD-------------------ABDA--- DCDBA-------------------BBCADAC DBCCB-------------------ABBABAB CDACDA-----------------CCCACCAA BDDBAB-----------------DBCCBBBD DDABDB----------------AADBBBAAA CABBBBD--------------CCDCABACDD CDDADBBCD------------CACDADCBDC CDBBBDABA------------DCCCDDADAD CACDACABAC----------BCBCADABBBC CCBCBACDCDB--------BBBDBCADACAB ACACAADBADCA--------DADCDA---CD DBCCADCDACBAADCB------DCCA---CA ACBDBBDBCABADAAD------DD-----AC ACDACBBADBDDBCBA------DC-----BB AADDBAADDBCCBAAB-----DBD----DBB DCCCBDACADDDABAC------DA---DADA ACCBCCDBADCCCDD-------ABCDAAABD ABDBCCDDADDBBCA-------AAAADAADD BACDBACBCCDCDCD------BBDBAAADBC BBABABACBBCBDAD-----BBBABCCBDBB CDCBBCBCBDBBABA-----ABDBABACBBA CAADACADABABDDC-----BBBBDCCBCBB 
DD------------------------BBCDB BC-------------------------B--- AC----------------------------- DBB---CC----------------------- DADBDDBBA---------------------- CCDBDBDDB---------------------- CBBC-ADAB-----------------D---- DCBDD-------------------CAD---- CACC--------------------BDD---- BCDA--------------------DBAC--- ACAD--------------------CDCDACD BBCBC-------------------ABDDCDC DBADAB-----------------ABADCCCB ADBACB---------------DBCADDBACA ACCADC---------------DDCDCBAACC DDBCDDC--------------ADAAADABAA DBDBABBAD------------ADADAADCBB AABAABCBCC----------BCBDDBDBDDD CDACAABADCD--------DDDBDBC---BC CCC-BDCDBDCD----------CDB-----D BBCAABBCDCACCACA-------C------A AADAAABDBB----AD--------------A CBBCCDCCBC----CA--------------D ABACBCDCBD----AB------C------BD DDCCABBBCBDBABAC------------BCA CCAAABADBADBABB--------A---CCCC CBCDACDCCCDBCDB--------ACBBBACD BCACBADBCACDBCA------ADDCDADADA DCAADCBDAADDBAA------ADDCABCBAB CBCCCAACACDBA--------BBCADCBDBA CDDBDCDAADDCC--------BAAABBDBAA 
BD------------------------DA--- BD----------------------------- DB----------------------------- DD----------------------------- CDDCBBDCC---------------------- CADDCCDCA---------------------- DBB-----D---------------------- BCCB--------------------AAD---- AAAB--------------------DBD---- DBAB--------------------BBBB--- ABCD--------------------ABADA-A BCAB--------------------ABACBCC -CBD-------------------CBDD--CC CACCCD---------------DBDDAD-DDD CADAAA---------------DABDCD-CBC B-DB-AC-------------------C-CBC D-BBDBDCC------------CBAA-AABBC A-DCBACADD----------BCACDDBDACD BA-A-ABABDC-----------CAD-----C CDB-BBAABCDA-----------BB------ DBB-DAACAC----AAC------C------- ABAB--CBA------AD-------------- CBCAD-BDC------DB-------------C AACBC-BDD------CC-------------D BBCAD-C-AB-----C-------------AC BDDCABC-CB--DAD-------------BAC CBACADBBCC-ABCB---------BAAAACD DDBBABADAABDBDB--------ADABDDAB BCBCDCBAAABCA---------BCBDCDCAB ACDBDBBCBCCA---------CBDBACACAB CDCBABBDCBDC---------BDDCABBCDD 
BC------------------------DC--- CC----------------------------- DB----------------------------- ------------------------------- D-----AB----------------------- C-C---CDC---------------------- ------------------------------- ABB---------------------BDD---- BCA---------------------CDC---- ------------------------------- C-AD--------------------A-DC--B D-DB--------------------C-A---B ------------------------------- -BB--C---------------AA-BAC-ACB -DB--B---------------CD-BCC-DAC ------------------------------- D-AC--CCB-------------CBB--DA-C D-D-D-CBB-----------C-CAB--AC-D ------------------------------- CC---BD-CDB-------------A------ CD----C-BA----D-BD------------- ------------------------------- D-AD---BB------D--------------C B-DA---DA------B--------------A ------------------------------- CAB-C-C-----CCC-------------ABA DCA-C---D---DCC-----------A-BCB DBCBDADCDCACDABD-------CADCACDD AACCDDCCCACBB---------BBDBABCBC DDBD----BBCC---------BCBABABACD DBDB----CDBA---------ADBDBBADCD 
A-------------------------AB--- ------------------------------- ------------------------------- ------------------------------- ------------------------------- ------------------------------- ------------------------------- ------------------------------- ------------------------------- ------------------------------- ------------------------------- ------------------------------- ------------------------------- ------------------------------- ------------------------------- ------------------------------- ------------------------------- ------------------------------- ------------------------------- ------------------------------- ------------------------------- ------------------------------- ------------------------------- ------------------------------- ------------------------------- ------------------------------- ------------------------------- ABDDAD-BBA--CAD-B--------BDCCBA ABAC----BBCCD-----------DDDADCC BAC------BDC------------CACBADD DCC------DBB------------DBBDDBB 
------------------------------- ------------------------------- ------------------------------- ------------------------------- ------------------------------- ------------------------------- ------------------------------- ------------------------------- ------------------------------- ------------------------------- ------------------------------- ------------------------------- ------------------------------- ------------------------------- ------------------------------- ------------------------------- ------------------------------- ------------------------------- ------------------------------- ------------------------------- ------------------------------- ------------------------------- ------------------------------- ------------------------------- ------------------------------- ------------------------------- ------------------------------- ------------------------------- BADC----DDC--D-----------DCDBBB ACA---------B------------BDBDAC DCB---------C------------BAAADA 
------------------------------- ------------------------------- ------------------------------- ------------------------------- ------------------------------- ------------------------------- ------------------------------- ------------------------------- ------------------------------- ------------------------------- ------------------------------- ------------------------------- ------------------------------- ------------------------------- ------------------------------- ------------------------------- ------------------------------- ------------------------------- ------------------------------- ------------------------------- ------------------------------- ------------------------------- ------------------------------- ------------------------------- ------------------------------- ------------------------------- ------------------------------- ------------------------------- ------------------------------- BBB-----------------------ACCCB ACA----------B------------ACADA 
------------------------------- ------------------------------- ------------------------------- ------------------------------- ------------------------------- ------------------------------- ------------------------------- ------------------------------- ------------------------------- ------------------------------- ------------------------------- ------------------------------- ------------------------------- ------------------------------- ------------------------------- ------------------------------- ------------------------------- ------------------------------- ------------------------------- ------------------------------- ------------------------------- ------------------------------- ------------------------------- ------------------------------- ------------------------------- ------------------------------- ------------------------------- ------------------------------- ------------------------------- ------------------------------- CADA---------AC-----------DBCDA 
