model
name = -141-wall_wdoor_ext_semibrick
size = 31 31 15
scale = 0.05
origin = -y
material type = toon, lighting = smooth, deform = 1 1 
  colors = A:#555 B:#4B4B4B C:#353535 D:#5A5A5A
voxels
DACBAABBCCADACBBCDCADACDBDAAAAC DBCBADDCBCACABDDDDBAACBBBCADDDB CBBBBBBACDCBCDDCDDCCAABDDACABDC DBADDDCACACCBABCDBAABDBDCCACCAD CDABAADCAADADABBAABACAAABABCBBC ACACACADACBBCDCCACCBCDCCBCADCCD CBAACADADBADBAAACACABBBADBBCCAA ACADACBDACDCDBBDABBBBCBBDBDACDD BCABCDAABADDDDBCADDBBDBDACAABCC ABDDAADACAAABBDDDBDBABCBDCAADDC AAABABABBDACDCDADACCCBDBDDBCDBD CCCCDACCCBBDBACBDDAABCDAABDCCBB BABAAAABDBADCADBADCBDDDDDCAADCC BCCCDABABDCADCBBACBDADDCAABBCDB CBCACBDBABDCBCACCBACDADBCDADADD DCCBDBBDBCCCBCDADBDDBCCDCACACCB BDCBBCABCDDCADACADDDDDAABBDCDBD DBBABABBAADBAACBABBCACBBAADCAAC ADBDDDBBDBBDDBDACABCADCADCCBBDD BBDBBADCADDBABDADDDBDBDCABDACAA BCBDCAADCCBADDBDDBBBBCCCAAABBAA BADAADDBBDBBCCBCDDCDBDACACCDDBA ACCADDBBADABCACDBDCDABABBCCCABA ABCADBCBDCABDDDDCDCAADABADBDCCD DCADDCDBBADDACCDBDCDBDCCBADDBBD CDCCDADDCCDABCBDCCAAAADCABDBDBB DADDDCDBDBABBBDDDDDABCDADDDCDDD CCBAAABDBDDADDCCDBBBCBDACDCDCBC DBCDCDBAABAABBAABCABCCDDCCCACDA BAACAABCDDAACCBCBDADBDDACACAAAB DCBBBAACDACBCBAABADCDCCADACCBAB 
BACCABDBDCDBBBCCABACACDBBDACDBB ADCBBDDCDAADCDBBBBADCDCCDABDACB ABABACABDCACDDBCCDABCBCBCABDCAA AABABCBBDBCCACABAACDAACABACDDDB DDBABACBDBDCAAABBCBDBAACADCBDDB CCBCBDDADCBBDACDBCADDAABCACDABB CDAADDCBDADAAAAADCBDCADADACBADC CACCADBCCBCCBABCDADBCCADDADABCB CBBAADBACCBBABCDCBCABCCBDBCDAAA DABDBDCBCCACCCDCAAADBDCDACBDACA CAADCACDDCDCDBAACDBBABDBDDADABA CBADDDCABBACAACDBCACDDDBDABCDCA ADBCAADBADACCBBABACCBDDCACABBBB ACDADACAAAABDDABCBBDDDDDDAAABAB DCBAACABBDBBCBCDCBACBCCABCCBCCC DADDACDDACDBDADDAAAACACBDAACCBC BACDABBCAAACDAABABACDCCCADDABBC ADCADDBBCCBCADCAABBAADDCCADDAAA BAACBAAADCBDDCCCDADBABBDCCBCDCA BABCDDBABCBDACCCDDCDDCAACDADDBB ABADDCACBBADCBBDBBACDBCCBBADDBB DBACBDACDBBAACBAABBCCDBBACBADBA CCADCCDBBCBACDCCBAADCCBACCCCDBC CCCADCCDABCCBCCBBCBCCCCCADDDDCA CCABADDCCAACBACCDCBABCCBCCBDADA AAABDDDDADBBCBABCBBABAACBCCBADD BDAADDDCACBABBCDDDDBCCCCDCDAADC BDADACCDCDBADDDCACCAAAACBBCACBB ABDCACADDDABDBDABDCDCDACCBBCCBA AADDBBACBBCABBBAACBABDACBBBBBAA DBDCCBACBAACCCBCBDBBAAABCABDBAC 
DDCDAABBDACCCBABDBADBADBCBCCDCB ADDDDDDACDDBBBBBAACCABCADBCBCCB CADCADADBBDCABACBDDCBBABADCCCDA BBCCADBAABCACAABDABAABADCCDDDBA BDBBDCCCDADDCBDCBDABBCBDBCDDCAA CADBABDCCBBACDACBDDBCCBDBBABDBA CDBABBCBDCCABBCDDBACCBADCCADAAC CCBCDCACBBBBBADCBBDBBCCAADDDBCC DAADDBAACBACBBCDBCCBDCCDBBCCACB BBDADBADDAAABDAADBCDCCCBCDDCCAB BCDDACCCDCCCDCBBACBCAABABDABDCC CDDBBCCADCCBCDABBCDDACBCABCCCCD ADCDDCCDACCADDCABCAACABDDBBCDAA BADACDDABABADCBAACCDBBDBCBCDBAD BABBCAADBDBDBABBCBBBBCDCBCCBCCC ADBBBBAACBDDDCCCBCDABCCCACDCBDB ABADBABABCBDBBDBDBACDCBABBBDCCC CBACCBDBCDBDBADAADABDDBAABCAADC DADADADABCABBBACADDDCCBBCBADBAB BDCACDBCCDDDBCDADDDCCABBBCADDBD CACCCCCDDADDDADBAACCCAAAACABBCA DBCBCABABBAADCBDDDCCCACABDAAABB CACBCDDADBBDCADBCAABDBDDACDBBAB DDDCBABBBBADADCDCAABDDCBBBABBAD ADCBCDDDCDCCCBBBBCDBACABBCAACDD DDACDDBBCCACCCCABDBADCDCACDCDCC AABAADDADDACCDDCACBBDAAADDACACA ACADBBBBCCBADCCBACDCCBABADABCCD CCACCDCDADABDABDACDADADADABBBBA ABBABBAAABBADABAABCCDDDADBDDDBC CCADBDBBCABBDAABCCABCBDABCBADCD 
BCDCAABDBCDBCCCDCACADDDCCDABBDC CDCDACDBDCCCACCACAAABDBDABDCDAD BDDCAADBAACDDACDDCCACCADBDCCCDB DCABDDDBBDCDDBDAAAABCACDCAACCBB BCBBDADBBCBDBAADAAABADDCDBCBADB BACCCACDCBCCACDDBADDCDCABBDCBDC AAABABDBBDCDCDDBCBADADACABCBBCB ABBDADCABDDDBBDCACCDBDCACBAABDA CADDBBCACDDDDBCCBBBCBDDADCDACBC AADDADCCCBDDDCADCBDAAABBADBCACB ABBADBADACADCAACBABABBABAADDDDB ADBCBCBCBDDDABCACABCDDDDADDBBDB BDACDABABBBACBCCABBBBABDCDAAADC CBBDACABAABAABDBDCDCBAABDDCDDCD DCBBCABDDCBAABCDBACDADBDBBBCBAB DBCDAAABACBABCCBCBAAADCACBBAACD DCDABACCBAAAABADDBAAABBDDAACBAD BAABACDCCADBACDAAACBBADBBDCCABB ABBDCAABCABDCBCCCCDCDABDBCBACCB DCBCAAADAADDDBAAABDADCBBDBBBCAA CACBDDBCDBBBDCBACAADBDBAABACADD BDDCAACCCADDCCADBCDBCADABCCCADC BACDDCDBDAABCDCAACCCAADBCDCDDAC BABBBCCDBACBBBDAAADDDDACCBABBBB CCABCBCBCDDBBDCACDDDAADABDCBABA ABDDBBBDCBCADCAAAAADCDBDABCDDCA BACCDCBCBCCAABCCDDCABCADCDACCDA ABDBDBBAADBADBDCBBCACCBCABABCCB BBCDCCBDAAAACDACBCAAABADDBBADAC DCDDDADBCCADBDCABCDACACBDACBBAC BABCDBCDBAABADDDCBCAABADBCCBABD 
CDCCBBADAAAACDAAADACDCADAADAAAC ABADDCACAADDCCCDBCCADDCBBACCABB DAABCBADABABBBCCBCCCBCDDDDBACAB CACDADBCBBABBDCDBCACCACACDBDABD CADCADACCCADAACBBCBCADADBDDBDBB AACCDDAACCDDDDDCBAADBDDCBADABBC DADADCBDCCCBDCDDCDABCDBABADADDC CADBBDCCCDDAADBAABABCCBDDCCCDCC DBDCCCAACDACBBAABCCCAAABDDDDDCD BDAACADCDAADAAACACBDBCDCCCDBDDB CDCCDBDDAACABDAACDBDACBABDBCABA DCBBCCDABBAADBCCDBACCBCCBDDDCCA CACBCBDBDDDCBBCABBBBDAADBABDCDD DCDBCADDCBDADDDDCBDDCCCBADDBCCC BACADADCCADBADDBCACCCDAACDBDADC BAADABCDDCCBDBBABBBBBCBDACDCDCC AACCDBDBADDDABCADCCDABDBADBACCD ABBBACCACCAACBBACCCDBAACCBCCBBD CDBADCBCBBCCABBBBCABBADAACDBDBC ADBBDBCCBCAAADBCCBDACCABADDBBBA ADDCBAAACBCDDCBCACDDCCABCACCADC DBABADDCAABCDDDADDADCBCDBCCBCAD DBBDBACCCBDDBCBCCDDBDDCBCACADDA DACCCDCBADCADBBDBBABAABBADDBBBD CBADBDACABADDBDADCABDAABACDDBCD BCCCAAAABCBCDADDDCAACCBCAAADDCD CAADDDACADDBDCBAAAACCCABBDCDDAA DDCCDBCDBCDDBDAABDCBDABABDDBDAD BACCBCCBDABDCCCADCBBCCCCDBACACD BABBDACDBAADDDDCDDDBCABBCDADBDB BCCCAADCADDCADDCCAABABADAADADCC 
BBBBBAABACCADABDDBCBADADCAABABB BBBCADDDBBBBDBCCCCBACBACDDDBABD BBBDABDAAABABCDBADDAAAABDCCCDAD CDAAAADAAACBCCCCBBDAACCDBBCABAC CDBACCCCBBCBABDBCBABDABDCCADDCB CDCCCAACCDDABBAABAABCCDCBBDBBAB CACDADACDBBDCDCDBDDDCABABABACCC BBDDBBCBBDACBABCBDCABAAADDACCAA BCCBCCDCCDCADDCCCCDCCBCBAACDBBB BBBDDDADAAADBDBACBCAABDCBDABBAA CDABDBCCCAADDDAACDAAADBCDCCDCCC CABBADCBDADCCBCBBBBDAABDCABCCCD BBACADACBBACBDABCACBCACBBACBCDB BBCDDDCACDCDDBCCADBABDBCDCDABBB CACADDDDBABCCADCBCDCDDCDDBBDCCD BAABDCADCACBAAADBDAAABCDACBABAA BCCABDDAABCABDBBDDDDCBABBDCBACD CBDCBADCCDBDBBABCADBBBCDBACABDA DACCDACBACDBCCBCACAABDCBDDCDDAA BBAACACBDBBDBCACDBCCBAACABDCACA DDACCBAACDDADBDAADBACDDBBCADACD BCCABCBAACACDBAAAADDDACDBCBDDBB DACBBCCDDDDABCCACCCACDBBDCCCDAC AAABBADCAACDACCBCADCDBCDDAAADBB DADCACBCDBBCCDDBBABDAAAADADADDD CDDCBCBBDCADACACDABACADDBBDDBDB CCDCAADCBDDACAABCBBAAADCACAAACC AAABADABABDDBAAABCDCBBAAABADABD DCCBDDBBCDAADACDBCDDBDDDCDCBCBD BCDADADBCAACAADBCACCCBCDADCBBBC BCBBBBACDABBDBACBBDACDCBADAADDB 
DDDACDABBCCABABDBAACDABCCCABDDC CCDACDDCDCAACBDBCDDCCBABADBADCD BBBDDDCCBDAACDBDACDAADBAAABBDCD BCACDAACDDBCCCBAAADCDADBBBBCBBB BBDCDDDDCCCCCBAADDCDBAACBCACDBB DBABAABCCDBBACACCADADBAABBCDABB BABDBDCABCDBDDDAABBDBACBCDCBCAA CBBBBADBABABBACABBCCDABAABACBCA DBBCDBDDDBAAADBDCDDBAACBBDCCCDC CCCAAAABDCCBCACBADDDDADBDCDCADA BBABBDCACCDACCBCDBBCAADACDDACDC AACDDCDDCBDDDDDDCAACCBDBCDDBBAB DBDDCADABAACDBBBDABCCCBBBDBBDAC BBCACADCCBDDDDADABACCBADCDDBABC BBDCDDCCCDABCBBDDACCACCBADACCDB ACCCCDCDDBDDDCDCCABBBCDACCCBDDB BBAACADBACAACDCBACCCDCACDBCDAAA DADDBDAABDABABDDCBBABCBABDDACCA BBCDABDBDCBACABACACBCDADADDCAAA BAADDACBACBDABAAABBADBACADBDBDD DBCDAAACDBDDDBCBBCADABDDCADCBDA BABABBAABACABDDAAACDABDDBCDCADD BACBCACDABBDBBAACCDDCCBAACCBCAC BACCDBADADBCADAAAAAADDBCBAADCCA DACCBCBCBCCABADDCADDBBABCBCCCCD CDCABCAADCCDDCABABDDBBACBBCDCAA AAAADADDCABBBADAABCACAAADCDCCBA ABCADDBADBCDDDABCCDAAADBCBCBDAB ACCADDBCBCAABCADBBBABDADBADBCBC BCDBDADBDABCCCBDBACCBDCCAADACDA DACAABDBDBBDABCCCBCBCCADDBCACDC 
CDAACDDDB------------ACBABABCAB CDBCAAABD------------BACDBBCDAC CAAADDCBD------------DBACBCBABA ACCBACACA------------CBBCDCACCC CCDCADCBA------------DABBCCDBAC DBCCDDBBC------------ADABBACBAC AABDDDBAC------------ADCAAAABBC BBACDBDCD------------DBADCDDCCD CCABBCBCA------------DBDABCADCA BBACDAABB------------CDBCAADDCD BBCBBDDDA------------BCCBCBCAAA ADDCCDADB------------BCCAADBDCD CBCDADBBA------------AAACCACBDA BBBBCDABC------------ADDCBCBCDA DCCCBBADD------------ADBDCCADBC DACADBABC------------BCADAABDBA AAACCDCBA------------CCADDDDAAD DABCDBDCBC----------CBDAACBDBDC CDCDCBDCCCA--------CBDDBDACDDDD BBBBDCCCBDDC------CACDBDBDCCCDA DADCCDCCCAAAACCDDCDDCCAADCCDCDB ADBDACDCCAAABCAADBCDDBCDBBADCBB BBCBCACBBABBABDADCAABCCBBDCACBB ADBCDDACDDCAACBADCABACCBBCBBABA BCABABDADABBDCDDBCACDCBDCDCBAAD DCBDBDACBDDBDCBBDCDDDDDADCCDDCB CBBDDADCADADCDAAABBACDCCBABBCBC DBDCBBBDDBCCCCACDDBCDAACCCCDDBA BDBBBDBBBAACBCDBBBDCCBBDADBCBAC DCCBCACDDDDADBCBDBCCCDAAAABCACB DADBDCACDCACDBDADBAADBDDBCBCCBB 
DACCCBDAD------------CDCDDABDDB ABBBACDAC------------ABDDABDCBB CDDBAAADB------------DDADABADDC ABDDBBADA------------DBADCBDDAB ACBADCABB------------CDABDBBCBA CABBBBAAA------------ABADCACDCC BACCACBBA------------ABDDCDCCDD DBCDABDAB------------CABCCABCBB CDCBADBCB------------BCDBAACDBD BABBDADAA------------DCBDACCABB DACACAABB------------AABDBAADBC DCADDDBBC------------AABCDCABBB CABBABBAC------------ABACDACDBB BBCABDADD------------DBADCBDDCB DBDDDCDAA------------ABADCDCBAB AAADCACDD------------ADBADCAAAD CDDADCBDB------------BDABCACBBB CCCCCDBBBA----------BCADDABDBDB AACDBBACACA--------BABBBABCCACD CCBACDBADBAB------DBBADCABACBBD BCACCDBBCDADDDBBBDDDDCDBAACDCAC ABAACCBDABBAACACAADACBDDCAADDAD BCADDAABADBBDCBBCBDABADBCDCBACC ACADABCABDDABCABCADDACBDBACBDCC CBBACAAACDCDAADDABAACABBBADCCDC ABBADDDACAACDDBBCDAADDBAABBDBAB ACBDBDCCDBCBCBACCDCBACCAAABDCDC DDDDCCCDDDACCAADBDBCDDBDACDAAAB CDAAAABCCBBCCBDAABBBCCDACABADCA DBCCCCDABADBDCBDBBBDABAADBBADCD ACDABDDBADCABAABCBCDBCBABCCDDCC 
ADDBABBAA------------CCCCDBDCDA BAACACDBA------------DBBBBDBBAD DAADABBDA------------ABBBDCAAAD DDCCDBAAC------------DCACDACBCB CDBAACDBC------------BDDBACAAAD DCBBCCCBD------------ACCDCBABCA ABADDCDCC------------DCCBDDABCD DBCDCCDCA------------CBBBCDACAC BBDDCADCC------------CBBCCDAAAC CBCAAAAAA------------ADDCCAADBC CCBCDDDCB------------BDDADDBABC AAAAAABAD------------ADBCDBBBDC BDAACCABA------------DCBDDADCCC BCCBCBBDA------------CDBBCADABD ABDBBDCBD------------BDBBBBABAC BACDBAABD------------DBDACBDACB AADCCDAAC------------BDBDBBDABC ACADABBDBD----------ADBDAACDBAD BBAABDCBCAC--------ADBDBBACACDD DBDDBBCDABAD------BBADBBCCCDADD DBBACBBADACCAABDCDDDABAADABBBDA DCDBBADADBCACCDADCDDDBDABACBBAC AACCADDACBDABBABAABDAADDCCCDABA ADDDCAADBCAAACDBBDDABADBBCCDCAD BAADABDCADCACCCCCCDACBBBCBDCCBB CABCCBCCCAACACABCCCDBCDABBCBDAD AABADACCCACAACBDDBABDABBCDABDBA CCBDDADCBBCCDABAABBACBCBBDBDABD AAACACBDDBACBBCBACBABDCBBDBBDDA BAACBDBBCCADBBCABDCBACBDADDCBBB DDBBCABBCDBDCABADDBBCAABBABDBCD 
CABACDCAD------------BBDBCCDCBD DAACBACCB------------BBDBBABDDC BCADABDAB------------BDCAADBDBC ------------------------------- DCCBBABDB------------CADDDDBCAB CCBCADADD------------BCCACAADCC ------------------------------- DCDCDDCDA------------DCADDDCDAB ADDAACBBD------------DBAADACBAB ------------------------------- CDCCDCDCB------------BAAADBAACB ACDDDDDAC------------BACDCBDABD ------------------------------- BACDACDBD------------BCACAABDBB BACAAABCA------------ACBACACABB ------------------------------- BADBBADCA------------ACDDACABDB ACBCCCDBCD----------ADAAABCDBCA ------------------------------- BACAABBBBBB-------CAACBAADADCDC CBBDCADDDACCDABCBBCBBBBDCDABADC ------------------------------- AABAADCCCACACDCBACBCBACBADDDCCC ACCAADADCBCCACBAAAACCDACCBCADBC ------------------------------- CCDCCBCCDCCBDAADAAABBABDCAADDDC CDDBBDCDBDBBDBCDADCADCADAADBDCD BCBCACABADABAACDABACBCACDADDDBB CBABACBCBBADBCCADDCBACCDADABDAC DABDAABDCCBCDDCBDBCDAAADBCDCADC BBBAADDBADCACBBADBADDBDDDDACABB 
AADBABBAA------------CABADACAAC ------------------------------- ------------------------------- ------------------------------- ------------------------------- ------------------------------- ------------------------------- ------------------------------- ------------------------------- ------------------------------- ------------------------------- ------------------------------- ------------------------------- ------------------------------- ------------------------------- ------------------------------- ------------------------------- ------------------------------- ------------------------------- ------------------------------- ------------------------------- ------------------------------- ------------------------------- ------------------------------- ------------------------------- ------------------------------- ------------------------------- AACBDDDDAABADBDAACBDCBDDADADDBA CDDCAACAADDBACBBDACCAABBBBCBCAD CADCBBAACCDBACDCCBBADDCACDBBCAB DCDBDDCCDBAACBDACABDDABDBDBCACB 
------------------------------- ------------------------------- ------------------------------- ------------------------------- ------------------------------- ------------------------------- ------------------------------- ------------------------------- ------------------------------- ------------------------------- ------------------------------- ------------------------------- ------------------------------- ------------------------------- ------------------------------- ------------------------------- ------------------------------- ------------------------------- ------------------------------- ------------------------------- ------------------------------- ------------------------------- ------------------------------- ------------------------------- ------------------------------- ------------------------------- ------------------------------- ------------------------------- ADBCDCCCAAACCABCCBCAAABDCBBABAB BACABDAAABDABCAAADDDCBDDBBABDBB CADAAACAACCACBDDADBDAABCADDADBC 
------------------------------- ------------------------------- ------------------------------- ------------------------------- ------------------------------- ------------------------------- ------------------------------- ------------------------------- ------------------------------- ------------------------------- ------------------------------- ------------------------------- ------------------------------- ------------------------------- ------------------------------- ------------------------------- ------------------------------- ------------------------------- ------------------------------- ------------------------------- ------------------------------- ------------------------------- ------------------------------- ------------------------------- ------------------------------- ------------------------------- ------------------------------- ------------------------------- ------------------------------- DBACDABBDBAAABDDDBDADABCADBBCCC DADADDBADACDACADADABACDCCCADCBD 
------------------------------- ------------------------------- ------------------------------- ------------------------------- ------------------------------- ------------------------------- ------------------------------- ------------------------------- ------------------------------- ------------------------------- ------------------------------- ------------------------------- ------------------------------- ------------------------------- ------------------------------- ------------------------------- ------------------------------- ------------------------------- ------------------------------- ------------------------------- ------------------------------- ------------------------------- ------------------------------- ------------------------------- ------------------------------- ------------------------------- ------------------------------- ------------------------------- ------------------------------- ------------------------------- AACBDCBBADBACADBDBBBCDBCDABCBCC 
