model
name = -154-wall_ext_brick_broken
size = 31 31 15
scale = 0.05
origin = -y
material type = toon, lighting = smooth, deform = 1 1 
  colors = A:#353535 B:#5A5A5A C:#4B4B4B D:#555
voxels
CDBDDACBABCCABCDAADCDDCDDDAADDA ABCDBDBAAAACDAAABCBDCDADDBABCDD DACACBBDDAACBBCACDBABDAACDCBDBA CBDBCDDDAAACBAADBADABADCCBCBDAA AABCBCDDABADDACABBADDDDACACBCCA CCDDABDDBBBCCBABCCACABDCACDBDDA CDACADDBDDDCDDAAABAABBBBCBBCBAD DACAACDABCDBAAACACDADBCABBDAACC DBDACACDBCBBCBADABCADABBBDDBBBD DCABBDBABDDCCCBABDADCDADCACAADA ACDBDDCDAAADCAABCCABABDDBDAABAD BDBDBCDABABDADDDCCCDBAACACCDDAD DBCBCCCCACDDCDABACDDCAAADACCBBA DDAAADCCABBABBCCACCAAAADCBDCBDC BAACDCAAAACACDABDBDAACCDBAADDBC ACBACACAABADBAABADCCCABCABACCAA DCABBBACDBCDBAAACBBAAABCDBCADAC ACAAABDBAACBCADBBDABBABDACCBCCD CDBCDDADBCACABBAACCCACCABCBCAAA DDCBACBDDDBBDCCCCBBACDDDDBDDCCC BADBCDCCCACBDDDCBCBCBAADDCABACC ACAACBADADABCACDDDCDCBDBAADDAAD ACACDBDDAACCBBDDACABAAADDDDABDB BCDDDCAABCCCAABCDADBDBAAABDDACA DBBBDDBBCAADDADDDABBCCDABCDDDBA ACAABABCBDDACBCBADCBDCDABDABADB AAADCCBACABBDCDCABACBCCCDDAADCC CDDDCABDCCABBDCADCDCDCDCBBCDBBA CADAADACAACBBCCCBAAADBBACABCABC CBABABCBCCADADDBCADDDDADBBCCADD DADDBDADAADDAABBCBDDDBCDCABAACD 
DABDDDADCCDBBAACBCDBDCDDAACDCAD AADDADAABABBCBDABBADCDADCABCCBC BAABDAABDCDDCBBDBDCADCABADBDDCB BBAACCCCDBBBADABBCBCABDBDBDCCDB BCCCABADAABABACACBCABAABDABBBBB AACBDDADBDBDDBCAACACCDCBBDADDDD ADBCDDDBBDBAAABDACBDCADABDDBDBB BBDBDDBABAACBCABCDCAABAADCCDDCB BADBACAACACCCCDBDCADDBDABDCAABD DCADAACBCCBCCCAABBDADACACADDBCC BBABCDBABDBCCADCCACDDDBCCABBDDA BDBCBBBCBAAABDBABDAAADCCBCADDAD BCCDDBDAADCABDDBBAACABCABABBDDD DBADDBCCCADCBBACCABBBDAACBBACBD DDBDBABCCCDBCDBACDBAABAABCCBBAD ABACACADBADCBDABCBBBDDCAACACBBC BBCDCBADDACCBDBCDABCCDABBDDBCDB CBADBCCBDCCCDCCBACCBAACDADBADBC DBDBDCCCBDABDACCCDABDBDCDCBDDDD DDBDCCCAABBBCAABBACAAAABBACCBBA DABCCCCDCAAABDBCBCABDBDBDDDBAAB ABCBCCCADDADBCABDCABDBBABACCBCD CACADBDCCBBBBDAAADCCACDDBBBADAD AACBACDBADACCBBADCDDACBCBBCBCCA CDABADBACBBBDBBBCDAACBCACDBAACD ABDDBBCCCADDCBCCCABABCADDDCCABA DACDABDADCDDAACCBCDABDCCBBABAAA CCDBBBBBAAADAADDBDCCDBACABDBBAB CBAADADAADBCACAABCCDBAADABDCCBB BDBCDDCDCDDDCACDACCCCBDDABDCBAC BCBABBBBCCADBCDABCCBBACDCBAAACB 
CDABBBDCAADCCCABBBBACBDDCBACACB BDBBCDCADDCCACCBCBDAAADAABCDDCD ACCBCBCDABDBADABAACCAADDABBBCAD ACDDACBAAABCDDBBBCDCBBDBCDCADAD CCDBBBCDBCCAACBADCCCBDCCBBBCADA CBDBABAAAAADBBDDDCABCDCCBAABDDC CDCAADACBDACCBADABACCBAACABCDCD AAAADDCCDDCDDBABDCACBBCCDCCACBD CBDBBDABCBBDDAACACDDCDCDBDBCCAA CAADBABBBAACBCCBCDBCBBCCCADBBCC BCDACCBDDAADDBBDBCCAAADDCDBABCB BCCDBBDDBACADBBCABDCACADBDCBAAD CDCCCCDCCADBBCBBBBACBCBADBDCBAA BCCABABDDBBCCDDBCADBBABDAAACBCB DADCBBACBDABDDDAAABBBDDCCDACCAB BAADBDABDABDBDDDBCABBCACBACDABD DDCCCBACADDCCDBBCBBBCBCDCAACABC DAABBDDDACACBBABBBBABDDBCDBCCAD BCDCAAACBDDDBBCCABDBCDABDACABAD DDDDABBCBAADCBCDDDDACDBABACBCBD DADABABADBCDBBDCBAAAABBCAAABACB ADDCBCABAAAAAADAACDCDCDCCDBBABD BBCDDBCACCDBABBCBABDDCBBBCBDBDA BACABCDBBCDDAABDCBDBACBACDCABAD CABCDDBBCBCDCBDABCCACBAAABBCDCD BDADDADDCADBCADBCCCCCDACDBCCADA BDDBBABAADBBDDBBCBBACABBDABBCCA ABBCAABDDCDBAABBDBDBDDABCBADCDA DCDDCACCCCCCDCBBADDAABBBCCDBBBD CABAAABDDDACADABBABCCBABADDBACD CBADDBADAABCDADCCDDDDDAABCDCABC 
CABAADCAABBBDAAABDADCBDABCBADBD ABDBBDBCBCCCABCDBCADCCBCDBBBADB AACCDDAADAACCDDCDCBCBDABCCBBADD DDDAAADCCDBAACACAACCDBBBABBCBCB BDCBBDBBCDBCCDBCDADACDADBCADDAD CADDACCDBADABCAADAABADAABACCBBB CCBDCABADCCBBBCAABBBACDADBBBCCD ADDACDDCDDDAABBCADCCACACDDDBDBB DCCAAACACACADBCDACBBDACDCDCCDAC CBDAACADACCCCCCAAACDCDDBDDADDDB CABABABCBABBBABABAACBCCDCCDDCAD CAADDDAABACACDBABADBDDCADCDCABD BADDCBADCACBBDADACBDBACCCACBAAA BDBDDABABAADACBAAAACBCDCABDBBCA BDBCAADAADBABACAACACABCDDBBBBCD ACBCCBDCCBDDADBABBCCCBACCBABCCB ABDBBDADBCAACABDBDBACCCABDCBDCB DDDBDDBADCACBBCDACCBCABAAAABCDB BBADDDACCBBDABACDCDBCDABADDDDCD ABCCCCCDACCDBDCDDDADCADCBDDCDAB ABBCDCBBCAADDCDBADDDBDDDCBBABAA CADBBBBDAABDCBDBDBADCCBDDCCBBAA CCAABADABDCDDAABCACCCCCDCACBCCB BAACABBCBCDABCCCDABCAADBDABCCCA DCCDBABDACACCAAADABADDCADCCADBB BABCCADCCDABDCDBABDDDBCDDDCDBAB DCADCDBCCBACBDBBADAADDBACBACCCC CADACCCBDDDBDDBBBADCACADBCBBABB DACDDCDDBCDACCDCDBDAACABBAADBDB BCDCBACDDDBDADABCAACCBBABCBACCA CDCCCACAABBADDAAABAAABCDCDCAACC 
CBCDDBBBDACBDAADCAAACDBCCAABDDB BADCCABACBAADACACDCDCDAABCBABBA CCCADDDDCBCDBBBAADAACADCDDBACAB DBCCBCDAAABABCCCDCBBDCCDADDABAA DACBBDACBACBDDABDADDBCABACDACAA ABCADCBACBABACCCDDCACBDBBACBADB CAACBDDACCCDDCDADDACDCAACCACDAB CCDDDCCBCACADCDDBAACAABBDBDABDA AABBCDBAACCDCDCDACCAAADBBDCADBC ADDDAADABADDBCBBDACABBBBACBDCAD CAAAACBBBACDCDBCCACABBABDADDCBD CABAADBCBADDCCDAABDDADADCCACCBA CDDCABACCAAAACCBABDBDDBCBCACABC CCCABADCBACCAACADBDACDCAAACAAAB ACCDADAABBBDADCDCADCBCAAABAABBA BCACDDDBDADCDACCCDBCDDCBDDADDAD BCDCDCADACDAACCCBBDCBCCAACCAADA ACCBDDBACCBBBDDBCCCBDDABCDDDCBB CADBBBADDDBDCADCBDDAABDACDADBAC BABCABDBDCCDBDBCACBADCABBDDBCCC BCCAADBADCDDADCABCDADBDCCBBDDAC DBACCAADCCCDDBACBDBCCAACBBABCDB CBDDABDABAAAAABBDACAABCBCDADBAC DADDADBCAABCDACBCDBBACBBDAACDDC DDDBDDBDADCCCABDCDBACBCABBCACAB ADCDDCBAADDABDBBBBBDACBBBBABBDA DCBABCBDBABCBBADBABBBBAADBDBDDD BACABADADCCDBDBBCAACDBDBDBAACBA CCDADDCACDBBDBABCBDCDABDCBBDADC BCCADBAAABDBCCDADAAAAABDACDAABA DBBDBADDCAABBDDBDBDBDADCCDDCBBC 
BAADCDABBDCDCDAC---AACABABBAADC BCBBAACADACCCCDD---DDB--DCBABDB ACDDACBBDBACDCDCCACCDD--DDDBDDD ABDBCABBACAABDCBCBADCCDCCADDAAD BABACAAABDADCCBDBDBAADCDBABBADA BCDCAABDBABABCBBCDBAADDDAADCCAD CAABABDCDBDCDBCACCABCDAACDBCCDD CAACBBABAA--DDBAABBADCCCBDACBAA BDABBBCCBD--DBDCCBDCADACABDAADC BDCDCBADAB--BCABCDAAACDDDACCCDA DDBBCBACDBCADADBBABBDBADBCAACDB DADCDBBABCBAABCBCBBCDDBBCBBDDAA AADBCCBABADAABCDBCBAADDBBCCDABA BCABACADBBACCBCCDDDDCBCBCABCADA BBABDBABAACCDDBAADADDADDDBACBBC ACDBADCDCDCBCDCACCCADABCDAABBCA CCDABDDDBCADAAABDCABCAABDBCDABD ACDCAADCCDCACBDDCBDABBDCADACADB DACDADDDAADBABCABDBBACDBDABADCB DABDCDCADABCCDDDCCADBDACDCCBBCC ACDDCBAADDADBAACCACDABADDBAABDD DCDACADBDCBDBBAACDBBCDDADACADCD BAAABDADBCDACDDDCABBDCBCADDCADB ACADBBDDACBBDACABBBDBCCDDBBACBD CCCDDCBCAABBBDAABAADAABAAACDBBD ACCDCCAADAADBDABDDDCAADBAAABAAB CCDDBBDBDCAADDDCDCBCBDCACCCDDAC CBBABBBADADAAACABCDBBBBABADBDBB CCBDDCAACCDDADACCBCDDBBACCBCBDA AADABCDBDBABABCBCDCBCCDCABCAABD ACDCDCDABCCDBACDABDABCDBDDBDACD 
CBCBDBDADDADBCA-----DA--BAADADC ADCDDCCACDCDDCA-----C----ACCBBA ADABDDCDCADDCACB---DD----CDACDB DABADDBDBABDBDABCACCBD--AADAABB ACABCCBBDACCCA---DCCB---DCCAADC AACABAADBBBCCD---CACB---DDDAADD ADCBCBBADA--ADDDCBDBA--BCDBDABD CABADACAA----DDCBCADBADCDCBAADD CBACCCDAB----DBCACBABBAABABABBC BBCAACCCA----ADBACDCDBABADDBCDC DCDDDACCAC--BBACBDCBBDDDBCCACDC CADDDABCADBACCCBCBCDDCDABCCADDB ADBACBADAAAACBABCAABDCDCABBDDCD BCABCABDDCBDADDABCBDCBCCCAAAACB ADDCCACBADDDBAACDDBBACDBBACCDBB CBCDDDDACDADBAACDAAAABDCCAACCBB CCCBADDCADCBCBBCAABBABABDDACAAB BACCBADDADDBCDCDCDBDCBACBCACDDD ACCDACDDBDBDAACABDABDACBADDBAAD BADCCCDCDDCDDAABBDACBBBCDABDBAC DCCCDDBBCADABDBDCCCACDBCBDCAACA BACDCDCCCDBCDCBDBBBCBDDDBACCBBA DABDCCCCDDCCCDCCDDAADBCCDDBCDBB DBACACBAACBBBCBCBBDCCBBDBBDACAA BDAABCABABACCAACCCDBBDBADADCACB CCABDBBCBDACADCDABBCCBBCABBAAAC DDACCDCDBCABDADAACDACCCBBBAAABD CADDDADBABCDCBCBDCCCADDCBDACCBD AACADDBABCBABABABCCACAAAAAADBBD BCCDBCDAAAADAACDDADBBBDABBCACBB BDCDDBBAABDCDDBDABBBBABBACDACCB 
CABBDDADCABCCBC----------DCBBCB BDDCBDDBDBACDBC----------BBCDAD DDCCBBAAACDABAAC----A----ABCBBD CCAAABCDCCACBB---ACAC---CAADABA BCDADACDDDCBA-----CA-----BBCBDC ACADCDDDBABCC-----AD-----AACCAB CBAACCCDBD--DD----------DCBACDA CDAACDBCB----CCADC--B--ACDBBBAD DDDDBCBBB----AABBCBDDBACACDAAAC ABCDBBBAC----CBDDBCBDCCBAACCCCA DDAACAABA----ABCDBBDDAACAACDCCD CAACDDCCAA--D--BCBDBBCBBCDBCCCC ABABCBBCCACBD--DDCBBDBAAACAABDB BADBBDDDCDABCDCBBADDDBADCADBCCA CDBACDDDDDDBACCAACCCCDDBCBACDAD BDBCADBCBCDBBACBABCBABCADDCABAD ACBDBBCBDBBDADAAACBBCDDACCDADDD CDABAAADDCABABDDCDDBBBDDDCDDBAD DDDBDCACBDBBCDBCBACCBCCABDDADCD BBCDACACACABBCDCBBBCBBADAADBCCA BADABADCBCCABABCAAABCDCCABDDABD CBAAADABACCBBACDCABDBBAAADCCDAB AADBAACDCAACCACABBDCCDAACBDABDC BBAABDDCBDDBCACACCCCBACDCBCBCAA DDCCBAABACADBBABCADDBAABDDDADAA BBBDADABCDBCCAACCDAADAAACBACDAB CBBACADADBACBCCACBDBACBDACABDAB AADBDACCBDADBBDDDCCDBBCBCADACBD ACABACACACDDCABDACBBADCDBDBDDDD BABACBABCABDADCCABBCAABBBDBCCBC ADBCCDCDCCDBBCBADDABBCADDDDDCBB 
BDDDDCADBABCACA----------BBABBA ACABAADACACABBD----------BABCCC BCDCBBDCDBBADBCD---------DBCDDD BADDCBDAADBAD------------BABDCC BCCACDBDDCCB-------B-----DCADDC AADDABCDDC---------------CAACCD DAAADBABC---------------ADCACDC BCDCDB--D----D----------CAADDCB CCDC----D----D--AA--A--BBDBAABD BCBC----B----C--ABBCDBCCAADBADA DCAB--ADB-------ADABBBCACACBCAC CBACAABDAC------CCCADDBBCAADABC DACDDADCACDB----DBDDCCADBCBABAA ACDCACCCBBDBD--ADDBDDABADDACBCC DCCCCCCBBBBBB--CDCABAACBCAABACB BAAADDCCBDBDABAAABDABBACDCBACDD BCBBDBABBACBDDCBCDADCCABAACCBCC BBCCADBCABABADCBBBAADCDDBBCDDDD CDCDAACABCBCCCCCCAACDCBCBCDABDC ABCDCABDDCCABACCCDDCBABDBACDACD CAADBDCBCBAABCCCBBCBBDCBCADBCCD DCBABCDACCABDDADDCBDBCBAADCDCBA DAAAABACBAACAAACDDBDACDADDBCABD ACBCADCADCABDCADACDBABBDCADCBDA CBACACCAACDCACCDDADDABDAACBAACB BBDDAADAAADABDCAABCACBBCCDBCCDC DCABDBABCBBCADBCACAABBDDDCCBACC DCBCDBDCDCBBAAAABDDBBADCCBADABB BADCDCAAABBCDACADBCCCBBCABBBCCD DDADACDCDBCBCBABDDBDDDAADACBDAC BBDCABDCAABACBBBDBABCCBBBBBCCCD 
AACADCCDBDCADDA---------DABABDC ADDCDDCBCCBACDB---------DCBCBAA BDBCBDBAADCDBABB---------ADDBBC DABCCDABDDDA---C---------AACCAD CBBCBCADCDC--------------DCCACD BCBBBDDABA---------------CBACBB ABBCA---C----------------BABACD CBCC--------------------DCABCDB BCB---------------------BDDCBCC BAB----------------CD--ADADDABA AC------B---------CBC-CDCBADBBB BD----BDA-C------DDCDBBBA-CCDCB BCDAABDCC-A-----DADACBBAD--AACB CBDBDCBBABAC----BACADCCBAAB-BAD ADBDADABDDDA----ABADBDCADAD-DDC B-CACBDDBDBDB--ADDDABCADCDBD-BC B-BBADCACCCDDCCCCDCBCDDCDBBBBBC ACCDCBCDCDCDAAABAADBBDCBCABDD-C DCAB-BCADCCABCABBDDBBABADACAB-C CCBCDDADCCDDBCCDCACDABCBDADDAAB BDDACDAAABDCBDCDDCAADCCBDDA-BAB CAADC--ACDAACBDCAAABBCBBD--DCA- CCCDADACAAABBAADCCBCDDDBA-AAADB ACCDAAACBABCADCBBBADCBBAADBBDBC BBDCDC-CCCCCABBCCBBBAB--ADBBDDA BBDCCBCDAABBDAADBBBDDCD--ABBBDB BDDBBCA-BCBACCBBBDDCCCA--CADDDA CACBDCCAADCACDDABBABBADDABDCBDB ACADCDDBCACABDBBBAADDBBBCBADCCA ACDBAAABBADDBBCBCCAACDAADDAACAC ABCACBCDDACD--CDCDCBCABABBCBDDA 
ACBAABCD--CAC-----------ADACDBC DCD-ADA-ABD-AD-----------BC-DCC CCD-DBA-CBB-BBA----------AB-ADD ------------------------------- D-CBB-ABB-D-------------D-CCD-A A-BBC--BD-----------------CDC-D ------------------------------- ACB---------------------DDD-CCA BCB---------------------ACA-DBD ------------------------------- D-----------------ABD--AA-ACA-A B-----BCA---------BAB-----ACC-B ------------------------------- AAA-CAD-DAB-----AAA-ACB-CC--DCB ABC-DAD-BBD-----ADC-DCB-CBA--CA ------------------------------- D--BB-CDC-BAD-BAD-BCB-CCB-BD--D A---D-ABA-DAD-DCD-ADB-BAC-AA--B ------------------------------- ADD--DB-ACA-BCD-BDB-CCB-CBD-D-C BAD-C-B-AAC-BCB-BAB-CDC-BD--C-- ------------------------------- C-ACD--DB-CAB-CAB-DCC-AA---AA-D D-ADB--BB-DCA-BDD-BBB-CB--CBC-B ------------------------------- CDB-BC--BCA-CAC-BAA-BD----D-DAA BCD-CB--BCB-BDB-BBB-D-------DCA CAACCADDCCCCADBBABCAC----C--BCD ABBDBADBBBDCBACDBADBB--DDCDAABA BDDACCCACABC--DDAADBBDDCDCBDDAA CDCCCCCCDAD----BACBDBBBABCCCACA 
BBCBDDC-----------------CCADCDC ------------------------------- ------------------------------- ------------------------------- ------------------------------- ------------------------------- ------------------------------- ------------------------------- ------------------------------- ------------------------------- ------------------------------- ------------------------------- ------------------------------- ------------------------------- ------------------------------- ------------------------------- ------------------------------- ------------------------------- ------------------------------- ------------------------------- ------------------------------- ------------------------------- ------------------------------- ------------------------------- ------------------------------- ------------------------------- ------------------------------- AABCAC--CABDADC-ABAB---------DB BAACCABBBCBBACDAACCB----DD--BDC BBCBBCBADBCA--DBDCBCC----ABBACB BDBBAAACDAC----ACDCCCCD--CDDDBB 
------------------------------- ------------------------------- ------------------------------- ------------------------------- ------------------------------- ------------------------------- ------------------------------- ------------------------------- ------------------------------- ------------------------------- ------------------------------- ------------------------------- ------------------------------- ------------------------------- ------------------------------- ------------------------------- ------------------------------- ------------------------------- ------------------------------- ------------------------------- ------------------------------- ------------------------------- ------------------------------- ------------------------------- ------------------------------- ------------------------------- ------------------------------- ------------------------------- DBDABC----A--ADC-BCC-----C--CCC DADDDAAD--C--DBDD--CD-----BBACA BDBDCBDAADAB--C----CCA----AADBA 
------------------------------- ------------------------------- ------------------------------- ------------------------------- ------------------------------- ------------------------------- ------------------------------- ------------------------------- ------------------------------- ------------------------------- ------------------------------- ------------------------------- ------------------------------- ------------------------------- ------------------------------- ------------------------------- ------------------------------- ------------------------------- ------------------------------- ------------------------------- ------------------------------- ------------------------------- ------------------------------- ------------------------------- ------------------------------- ------------------------------- ------------------------------- ------------------------------- ------------------------------- BCCCBC--------B-----C-----BAAAC ADABABAB--C--B------DA-----BADB 
------------------------------- ------------------------------- ------------------------------- ------------------------------- ------------------------------- ------------------------------- ------------------------------- ------------------------------- ------------------------------- ------------------------------- ------------------------------- ------------------------------- ------------------------------- ------------------------------- ------------------------------- ------------------------------- ------------------------------- ------------------------------- ------------------------------- ------------------------------- ------------------------------- ------------------------------- ------------------------------- ------------------------------- ------------------------------- ------------------------------- ------------------------------- ------------------------------- ------------------------------- ------------------------------- CDBCAD-------B------AA-----ACDD 
