model
name = -176-wall_ext_semibrick
size = 31 31 15
scale = 0.05
origin = -y
material type = toon, lighting = smooth, deform = 1 1 
  colors = A:#5A5A5A B:#555 C:#353535 D:#4B4B4B
voxels
DCCCDADBDCADADCDDAACDBDBCBAACBC AACCDBDAABDABADDCCCDCBCDDBBDABA ADDDABAABBBBCADCABCDBABCAACDAAD DCBABDDDDACDCADCABBBADAAACBDDDD BBDCDBCABCBBBBADAAACCBABDABDDCB BDCAADBBDCDCCABDBDCCABBDBCDACDC CCADBCCDDDCCDDDDDDBDBAAAADDCBCA DBAABDABCACBBCCDDADDCCBBCDCCBCA BBBBCCACCBBCCADDBDBACCCCCDCBBBD BBABDCACDBDBADCCBABAADDBABBDCBA CAABCADDCCDCCBBCDCBBDCDCDCBDACB CCBDBAAACBBADCACCDDDDBABBACCBDB CACBACCBAABDADCDAABCDDAACBACAAD BCACCABAAADBAADADADCBBAADAADACA DCCBCCDACCCCCDAACBAADBCDCBACACA ADCDBADDCDCBDDADCBABCCABDABACDB ABCBAAAABBAACABAADDBAADCBBDCCCA DCBDCCCADCAAABDACBCBABDDDADADDB DDCCDDDACCCBABBDADBDCDCBADAABDD DBDACDBBBABDBCCBADAABDDDDCCBBAA BDDAABACACADCAAADBBDADCCBCAAACA DDBAACDCBDBCCDBABCADACBACABBDDD BADCCBCCABBCAADDABCCCBDACDBCABB ADBBCCDCADBBABABBACCCBBCACDBCCD ACDDBBAADDBCACDABBDADDDBAABCDCA CBDCCCDDDADDDDACDACCDDCADDAACAC ACAAACACCBCCACDDAACBCCBCCDACADD CBBAACAABBDBBBCCABDDCDDADAADBAB AADCBDBCAAABBCABCCDBBDBDCADBADA BADCDACDDBABACACCAACCACDBDCCDBA CCCACACBDCBACCABBDBCDDCDACBBBBA 
ABDBBAABBBBDBBCCCACBADDBCDABBCD ABADDCBBCBBBDDCCAADAACBACBCDBDA BDDDBBCACBDBDDABCACCBACBACCBBAA AACCDADBDBDDDBBACCBBDBDDDACCCDB DBDCCABCADCBBDAABBBCDBBCABBAACD DABBAAACACABCDADDABAADCAACBBDDA DBDABAACADBBABDDCACDACABDCBACAA BABDBADBDABBDABACDADACBBCCBCBCC ACCBDDBAAAABBDDABDCBBCACDADADBD BAACBDDDCDCBADDABABBDAACABBCBAA DABCADABCDDDDAABBCCBDBAABBABDDD ACDACBBABDDCACAADCABBCAACBCCCBA BBAABCBADDDBABBCAADDBCBCDDCCBCC CDBCAADDDDAABBBBBAADBADBDDCACBC BDDACCDCACAAAACCABCCADABCABCBBC CCAACCBBACAABDADAADCACACDACCDCA CCACCABDBDACADACDCCCDDDBADAAABA ABCCDADBCABCDCCDABAADDADACCAABA BAAACDBDCCCBADBCBAAABBCCDBDDBBD ADAAACBDAACBDDCBDBCDADCBDACDADD CADAADDCDBBCBABBCBACBAAADAACBCC AABBDBABDDADADCBACCDADCAADDCAAD ACCABACBBCADACABACAABADCBCDABBC DCCADBABBADDCADCADCACDCABBBCADB ACDCBDAABCDDBBBDAAAAADACCBABAAC CCBDAACBCBCCABBABBCDCBDADBABABA ADDBCDACBCCBBDDACCDCDBAADBBDACD DABAABCDDBDBCDBCDCDBDBCADDCAADB BCCDACDABCCCCDBDBCACAABBBAAAACD BBAACAADCBBDCCDBDCABDBBBCBBCBBB CBBDABDBADACBBADCDABBADBACDBBCC 
CDADCDAAADACDCCCCBBAADDCDABADCD DBBABBBBCBCAAADCBBBBBAAAACCADDD BDCADCCBBACBBDBABBDCDBDBCACDBBC ADDACBCCBADADBADDBCBCABCDBCDAAA ABACCCDBACDCABDCCDBCABCABADACCD CDDACDDCCDACBBCBABCDADBDADABACA DBACCCCABDCDCDBCAABDDDCAABCBBCD CCDCBCBBDAABDADBDCBDCBBABABDDAD DAABBABABCABCCBBBBCBCACBCDDCAAA AACCDCDCBDAAACDBDBDDACCACCDAADD BBBACADAACDDABDDCDABCAACACCCCCB ABBADBACBCCCCACABDCCDBBCCBACBAD ABCADBDDBCACCBDBBABABCDBBBCCACB BDDDADADDDDABCCCCDACBBDDCCDCBCC ABDCCACBABABADCDBBBDABABDACBADD CCDCACBDABCDDDCDDDDCACDCDABDBBC DCAABADBBBAAADADABBCAAAACBABAAC ABDBCABDABDABCCACAADDDBAAACDACA AACBABBBBABADBDACBABBABDDBDDBAC CCBADACDDAAAADCBAACDCCDDADDABBA CCCCCDDCABABCABDDDABADACDADDADD CACBCCCDBADBDACDDDCBBBAABCBCACC ABADAAAACBBBADBDDACAACCCCCCAAAD CCCCDCDDBACBCDCCCBCDABACDDAAAAC ACADABADCCDAADACDDADBDDBCCBDBCB DABDBADBBABCBADDDCDABCDDDDCCABA ACACBDBCBACCBDDDCACCDCCABAACBCC CABBCBBCCCCBDABBAAABACDDBCACACA DBBBCCAAABACACACDAADACDABADBAAA CDCDBACCACDDCDCCDADDACBDCCCADDA AADBDBCCDCABCACBCBABCAAAAADDCBD 
BBACAABCADCCBACABBAADBDCBCCDDBA DADDDBCACAADABBABCDCDDBCCDABAAC BBABCCDBCCCAACDDBCCADBCBACDDABD DCDBCBCCCADBCCABCCDDBDABBBDAAAC BBCACABCBACCCDDDBBCCDDCCCBDAADB ACBCBDBBACDCDACCDDCBBBCCDCBACBC CDBAABCBCDDCADADBCDACBDABBCDACC ABDDAADCBAABDAACDCADDBADBDCADCC DACCBABBCDCADCDCBCCCCDDBABDDCAB CBBADAACDABDCACAADBDCDBDCCCDCAD BBDBDCAACCDBBABADACBDCABBDBBCBD DCADDAABDBABBCCCDCAACDAABADAACB DBDBBBBBCCCCCCCCAABADBABBCBCDAD DCDBABDBACDDDDDCACAADBBCBADBBBC BAACBAABBACADACCCDABDDABDCBAAAB ADDBCDABABCDDDBDCABABBDCBCCDBBA CDCCBBADADBDCDCABCCDACDBBAACACB BAAADCCDBBBDCCBDDADDCCAADCADBDB ADDCDCCCBBBAAAACDACACDAABBDACCA BDDDAACCAADCDDBBDCADADDDCACDDDA BACCCBADDBDDDCBBBBBDBBBBCACAABD BBBDDBCADBDDDACCCBCBDDACDCCCCCA DCCBBACDBADACCCACCCBDBBCBADCCAA AABABCBCACDBAAAADDCABCAACAABBCC BCBBDDCCABCBBDBBABCADDACDACDACD BADDCACDAABADBBDCACABAABABBBDDB DBDCBDBABDACBBDBAABDDCBBCDBCABA CBABABADABCADAAADDAACACDBCCDBAD BBCDABCDDCADDBDABABCACCCACDADAB BDAABDBABBDCDADCAADDBCAADCDBDBB ABDDBBDBCCABDBCCBACDBCDCDCBABDB 
DBACABADCDCACAACDCCDBBCBBDBBBCD BBCABCCCBCCBADDBADDAABCBDCDDCCC BBDCBAABCBACBCCBCBCCACCBBDCDBCD BABCCBDBACCAABDABADCDAADAABACAB DCCCABCCCCCABDBCAAAAADDACABCDBB CAADDDAADCABAABABCBDABADCDCCCAC ABDABCBBACCBDDDDADBACBDCDBBCAAC ABDDDBDBDDCDACCAABDCDCCACAABDDC CCCACABCDBBBCCCCACBACABCDBCBAAC BDBACACCBABDDABBDCBBBDCACCDCAAD BDDDABABDADAACCDDCCCCCABADDBBCB CBDBBBBAABCAACDDDBCDBABADAAACAD DBDBBCABABDDCDCBBDBBBCCDDCDCABB AABBABBDCDDDBBCCDBBBADAACAABBAB BCDDBCCABADDABCBBDCDBAACCBBADDC CABCDDCDBCACCCCADCCBDDCCBDCCABA BAABDCCAAAAAADABABDACBCCCBBBDDC BCBBDCDADDABCBABCBDDBBADDBCADBA CDDBCDCAADDCDCCADAACACBBCDDCBBB BBBACACCDDADADCBDCBDBACBCCDBCBC ADCCCBBCCDABCDDDDDABACDCCDACCDA AAAABDCABDAACDBCCABACABACCBACAA AAADBDDBBABDAADBDBDADDABDAABDCD CABBBBADBAADDBCBBDCCCBABDDDCBBA DACCACDDBDCAABDABDBBDDDADABCBAC DBACBCDBBDACCCBCCCCBABABBDDDDAB DCCDDCADBAACDBADDCCDCBCCDCDABCC BACCBABCCBBCBBBBBCABCADACCCCAAD BADBAAACDCABACDADCBBABBDADACABA CCDBCBCCADBADCCABADADCBAAADBACD DDBCCDDDABCCBBCAAADAACCBDCCADCA 
ACBDABBABCACACBADADADCCDBDDBAAA BAACCADADBACCDDDACDDCBBACBADBBD BCDCABBACAACDDDCAACBDABCDCDDADC CAACAADABCCBADBDCACBCACCBADCABA DDBDDCBDBBCDDCCCDCBADBACCAACACB CBDBDCCBDABBADACDDCADCCACADBBAC CACCCCCCDCBCDBDABCBACADCBABABCB DCADACBDBCDDACCCBADCBDBDCCBBCBB CCDDCCDBADDABABBCDABDBBCBBBAABC ABCDADAACCCDDCBCAADDBCDCDBBCCCA CABBBBDCCABCDAADBAAAABCBDBDCAAC BBCBDBCBBAACBBBAABAABDDDBCAADAB BACCDDAADBCDDBCBBDBBDBDCCABCDAA BCADACABDAADDDBBCCBCBCCCCBABBDC CCCCAABCACADCDBCBBBACACDCABBACA BDBABBCABACDCADADBCCBDABBABABAB DDCACBBDDDBBBCBDDBBABBCABADAADD BCBCBCBDADDBACBACDCACBABDBBBBBC BBACBADDBABCDADBDBCBCBACABBCADD CAABDADBCDADCCDDBADACBDCDBCDCAB DACBDABBACACCAACBBCBDBACDDADAAD ABBCDCAABBBCBADADDCDACCAAABACCB ABADBBBDBDDABDDDDBCABCDDABBBBAC ABCABDDDDDACDBBDBACBABAACBBBADD DDCBDBBBBCCDACDDADDADBCABBACDDA DDACDCBCABDBDBDABCCABBCDADABADB BBAAABABDBBACDDBADBAADCBDBAAAAD CDDDCDBBDADCABADBDDCCCDBBAAAAAA DBACCDDCCABDBDADABBBCDDBBBCCAAB ACCDBBBCDDCBBCCDCDDDACDDDCBCABC DAACDCBBAABCDBBBDABCDCBDCADCAAD 
AAACCAABBDBBDAADBACACDDBDBDDABD AAABDDBBDAACCADCBABDBCBACBDAADC DBDCADBADDCBABCDCBAAACCCADBBADA CCBAADDBDBBAACCCCCCADAACAAACCCD AAABBDCAABCAABBDDBDBCDBACBDBACB BCAACCCABDDCBBDBBBBABCAACBDDAAC ACCCAAAACBDDBCBBCCCABCCBABDDBCC BBABACAACDACABDDDCBDAABACAAAADA BDDCBAAADCDDDBBBCDACCACADBCADDC ABDDCABBCDAADAADCCBDDAADCDADCCB CBCDCCCABCADCCDCCDDADABABBADBDD DDDDDBCBBBDDCAADCADAABBBDBACBAB ABDBDBBABCCAADDAABCCCCADBDDCCBA BBBADCCCAABDDADBACABBBBDCDCBCAA BDDACDCAAADDCDBDCDADABDAADBABDA AABDDDCABCBBDBBAAACDCCCADCBDAAB BBCDCDACBCABBDCDBBBBADDACABBCBA BDBDBACADBBDBCBBBABCAADADBDDCAC ACCCDBACDDAADDDACDBAADBDBBBDBBB DCCAABADABBABAACCBDDADCDCADDACA CCDDACBDBDDCBBADDBCCDCDBDDACABD ACDDCCCABBBBDCACABBABDDCBDDCDDA ACBAABAADADAACCADACBABCBCCDADDD DBBAADBBBCCACDCDCCBACACCADACACB ABBDADADDACACBDBACCBADDCBADDBDC CBDCDBCBDBCCBBCACDBDDCABADDCDBB AABCBACADDDDDDBCCABDBADACCDBBCC DCDBDACCCBBBDBABCBCDCCCACDDDBCA ABABBDCCDDDABCADBAAACBBDBBBAADD CBBDCACDBCDCDDCBBBADCACDBDBDBAC DDBCCCACBCDAACCADDBBACCCADCCCBB 
AADDCDACCADABADAABDCCCCCCDDCAAB CADCDCDBCCBBCAABCCDBABBDBBDCCCA CDADACABADBBACACAABBBBBDDACBDCC DCBABBBBBCACADCDBDDAABDACABAADD DDDABDBDDADABABDDBDBCABADDBDCDC BABCBCBDACABCABCABCADAADDCCDDCD BCBBDDDCABAAACBAACDDAACCCADBCDA DBCDCDACDACBCCBDBAADAACADBBABCA ADBACCACDBBCDBDBDABDCBABABACADA AACADABCDBCCACBAACBBAAABCADCABA BADADDCADABBBDDCABDBDCCBDABCBDB DACBDAACDCAABADACABBBADCCDBCDDD CBDCBBAACABAAABBBCCCADCDCAABDDD DABCADBACABBACAACCCBAAADADDBBCA BABCDCDDDCBDDAABADCCCCCDBBCCDAD DABBAABCCCABDBADDBBDACDCABBCAAC CACBCBDBCACCCBDAACBDDADDAACBACA DDDCDCCBCAACBBBBBDCCDBDBBCCADAC CCCBACCABCDBBDCACCBBCDBACBCBCCC DBCBCBCCCBDACBDDDCBCADABDADAABD BABDACACCADDADACADCDDAADBBAABBA DDDBADCBDDAAAADCBBDCDAABBAAAABB ADCDBACCCAADCACBDDDDCCAAACBBBBC ACBCDACBCBCCDCCCCAACDADBCAACABA ACBDABCABACABDACDDDCAACBCDCACAB BCACAAABCDAADADACBACDDBBBABDDAC CADABBDCBBBBACDBDCCBDDACDAADBDA CBBCDABDBCDCCBBDCAADDCABCCBCBAB ADDAADBBDAAACACBACDDBCBDBBDBADC AADABDBDCDDCDDCBCCBBDADCACACACC CBBCAACDBABABBABDBAAACADCCCCDCD 
BBDBBABCDBDBBBABAADDCCAACBAADCA BAAACBACBCABBACCCCDDADACABBCDBB ACCCCADDABCCCCAACAACDBBBBBDBAAC ADCBADAADADBACCCDDBAAADCDBACBAC ACBACACCBCDCCBAADDADADBBADACCDA ADADACACABCBBAAADAABACBDDDDDCBC DDDDAABBADCACBDDBDDBACBBCDDBBCD ADABDADCDDCADBCAABCDACCBADABADD AACCAABADCBCADADCABBDBDADDBDBAB AABDDCDDADBBDCDDDBDAADDCBAACDCC DADDCCCABDACCABCCCAADACDCCDDBBB BCCADCDAADCBACABDDDBABDDBADADCA AAACADCBBCBADCBAACDADDBDBADDBCD CADCAADCCDDACCCACACADACCDCCAABB DCDBDBBCAACBDBDCCADADBCBDBBCABA ABDDADBBDACBBDABDDDDBCAABCBDADC ACACACDDBDCDCCDBCBCDDBCBAACBDBB DDADCCDBCCCADCAAADBBAADDBDDDBDD BDABCDCCDDCCDDAABCADDCDBDDCDCAD ABCDDABCBBADDCABABDBBDDCABBAACC BBCCBAADCABDCCACACCDACBACABCDAA BBCACAADDBADBCBBDADDDBCBDCCDABC CDBBDABBDCBCADBBAACBCDBCDBDACAB CCCAABACACBACBCCCBADABDCDDDACBB DDCDABDCBABCBBDDDDAABCCBBCDCDDD DBDCACDCCDCACABDACBDBBCCAAADBDA BBACABCDADAACACCACABDAADBDDDBAC BBDBCCDCBDCACACBDACCCDAADADCCCD DCBAADBBDDCBABABBDCAADBBCCCAADB BCCDCADADDDBBDDACDCCBCCBABABCCA DBABABBADABBBDBCDDDCBBBCDCBDADB 
DBCDBACBCBCACDBCBDABABCBDDCBACC CBDBBBABBCAACCABCCBACBADDADCCAA CAAAADABADDCCDADCDBDAACBBADABDA DACDBABADCCBBBACDDDCADBADDDCBAA CBCBBAABBCBBCBBCBDAABADABBACCCD BBBADDDAADADABCBABACDBCDBDDCDDC DBCCCBBCAAADCDDDAABCCACBAACCCCC CABABBBDDDBDAAABBBBACBDCBCDBBDA DDCBAAAAACCDBCDBBDBDDBACAABDACA ADDABDDBDBABDABBDACCBDCACACDBAC CDCBBACDCDBBDAADBCDAACBBCACBACA BDBBAACBBDDBBDBBBBADBCACCACABBB CCADCADACCACABBBDACCDDACBDDCDAB CCCCDCACAAADDDBDCBBBACADDDBDADD CCDDBDABCBCDABBBBBDBDDCDCBDDABB DDBDAACAACBCCBACDDCBDDABBBBCBAB BBBDDBCCCDBABAADBDDDBBABBDBCACD BBCBBCBDDCBCABBBDDCCCABADDABACA BACCADCAADBCCADCBDCBDCBDDBCBBAB BADBBBDBBBCADBDABCBDBCCDADBADAA DDDDDDDCADBBBDACABCDADADDBAACDC CABBDAADDDBCCCDCADCBDADAABABADB CACBADBAACBBCBDBCADACBBCDDCDDBC ABBADAACBDBDCBBADCDBBAAAADDCDBB DDAACADCDACDBADCCBCDCCCCBBDBDCD DADBDBBAACCCDABABBBCDDCBADCBDBB CDCBBDCBBDBACAAACBDDBCCDBBCBDCD ACCDBADDCADBCDBDBACDBDBDCCABBCC BBDCAAABCBBCCAADCDDBACDDDABCDDA BDBADBDBDBDCBBDCBBCDDDAABACCCDB CBCCCBAACCCBADCBAACDCDACCAAADBD 
CBCAAABCDBACACCBABDADDBACAABACC CCDACBBCDCDCDBCDBAAACDACABBCBCA DCADACDBADBCACDBAACCDCDDCADAABA ------------------------------- BAAAAACCADAABBDCCBBCAADADDCDDBD DADDACBDACCCDCDCCABCAAABDBBACAC ------------------------------- BCADDACABDBCABCADCADCBCCBBDCCDD CBCBADCAABDBCACBBABBBDABDCBBDAC ------------------------------- AABADDBAADAABABDDDDBCCCBDACBBBC DBCAADBCCABCADCACDDCBCADDCBCBCD ------------------------------- ABDBDACCDBCBADBCBBBACCABDADCDBA ABADBDBDBACBDADBCCDBBAABAAACDDD ------------------------------- BDBBABACABDCBDADCCCAACBCADDCAAA ABCAAADBBCDAACDBCCBCDDADCDBDCCA ------------------------------- DCBACCBDCDACAAADCDBDBCBADDCBCBA ACBABABACDCCCCCACCACBBABBBCBCCC ------------------------------- DCCDDBCADDDDADAAABABBADBDCACABC DACCCAAABACBDDCBDBACBDDBDAADDAA ------------------------------- CBCACBCDABDCDDDDBBCBDADDCBDDDDA DBACCBACDBBCCACADACADAABBCADACB BABBACBDDADBCACDDDCAACBBCBBCACB DAADADAAACCADDBDDADACDCCCABADDC CBBACAADDCBCCADBABACBABACDBAAAC AAABBCDCDADDDBBCBCBBCACADADABAD 
CDADBDCCBBCDDDCBBDDDDDBDABCDDDA ------------------------------- ------------------------------- ------------------------------- ------------------------------- ------------------------------- ------------------------------- ------------------------------- ------------------------------- ------------------------------- ------------------------------- ------------------------------- ------------------------------- ------------------------------- ------------------------------- ------------------------------- ------------------------------- ------------------------------- ------------------------------- ------------------------------- ------------------------------- ------------------------------- ------------------------------- ------------------------------- ------------------------------- ------------------------------- ------------------------------- BACBBDACCADCBDCBBCDACCCADDADDDD BDAACACCCDCDDDCADCBADBBCADABAAA BACACDACDBBDCDBCBDACACCABDACAAD ACDCAADACAABBBCCCBAACBABCAABDAA 
------------------------------- ------------------------------- ------------------------------- ------------------------------- ------------------------------- ------------------------------- ------------------------------- ------------------------------- ------------------------------- ------------------------------- ------------------------------- ------------------------------- ------------------------------- ------------------------------- ------------------------------- ------------------------------- ------------------------------- ------------------------------- ------------------------------- ------------------------------- ------------------------------- ------------------------------- ------------------------------- ------------------------------- ------------------------------- ------------------------------- ------------------------------- ------------------------------- CCACABABCBDDCDDBADACBDBCDCBCDAA CADADDDCDDBADAADCBABBBCCDACDBAA ACCBABDBBBADDBACBCABBACBABCBABB 
------------------------------- ------------------------------- ------------------------------- ------------------------------- ------------------------------- ------------------------------- ------------------------------- ------------------------------- ------------------------------- ------------------------------- ------------------------------- ------------------------------- ------------------------------- ------------------------------- ------------------------------- ------------------------------- ------------------------------- ------------------------------- ------------------------------- ------------------------------- ------------------------------- ------------------------------- ------------------------------- ------------------------------- ------------------------------- ------------------------------- ------------------------------- ------------------------------- ------------------------------- BACAABBBCDBBDDBACABBDAABAACBAAD BBDABCBDBABCBBCAABCBDDCDAABBBBA 
------------------------------- ------------------------------- ------------------------------- ------------------------------- ------------------------------- ------------------------------- ------------------------------- ------------------------------- ------------------------------- ------------------------------- ------------------------------- ------------------------------- ------------------------------- ------------------------------- ------------------------------- ------------------------------- ------------------------------- ------------------------------- ------------------------------- ------------------------------- ------------------------------- ------------------------------- ------------------------------- ------------------------------- ------------------------------- ------------------------------- ------------------------------- ------------------------------- ------------------------------- ------------------------------- ACCDDBABBBCDBABDBADBCDDDBABBCBD 
