model
name = -183-wall_ext_brick
size = 31 31 15
scale = 0.05
origin = -y
material type = toon, lighting = smooth, deform = 1 1 
  colors = A:#353535 B:#555 C:#4B4B4B D:#5A5A5A
voxels
BAACDACBABCCCACCDACBADBCDCCDAAB DDADACAABABDABACCBADBBDDBDCCBAB ADADADACABCBAABACACDCDBDBBAADDD DDACDDCDBCDBABCADACDDBBCCCDADAA AACCCCAACDACBCDBBBADDCDDBADACCA CACDADAADCCACDBABCBCBBDCABABDBA CBBCCDAADBABCADDABDAADBDCBCBDCC CAACACDBBCCADAAAABABDBBADDCACCD CDCADCDBDAAAACAABDADCCCACCCCAAD DCDBBBDAACABABBCDAADCBBDBBBACCD DCCCADCBBBDDBACBCADCADCBDCCAACB DBDABDADDCCBCDBABBBACCBDABAAABD BACCDADDCCDDBDADDADADADBDDADADD AABDBBCAAABBDADAACBDDCBAABDCABB DAAAABDDAACCCBBDBCBBDBBBBCBBABD ACACBDADDDBCDCDBABBDBDCDCAADCCD BACADDACABACBCBCBCADCCDBDCADCCC BBACBCDCBAABBCDCAADADAAAACCADBB DCDAADDCBCADBCADBBCDBADBCAACACC CDAADDDABCADCDDDACDBDABCDACDABB ADCABBBBBDDBCACACCCADCACCDADBBA BDDCDAAADADCBBADCCDCCBCDDDADCBB CDCBBBCCADDDCDBBBBCDBDDABCBADDD DDBDCDACBADBCBCDABAABCCDABDDDDD ADBACBADCCADBDCBACABBADCADCBBAD CCDAACBABDDBABBDDDBDADBDACDDCBC CDDDCCCBCADDDACBDCABDAACCADADCD ADBADACAADDBAAADCCBDBABCAAACAAB CCBDBBABABBDDCDCADDCCAAAAADCBAA AADBABDABAACDCCCADBDCDCCDADCBCC CCADDBCDBADBABBDBBADDDADDCADDCA 
DCCBBAABDCBDABABCCBDBADCDDCBADA CCCBCBBBBDADDBCAABDBAAAACBBBACB BCCACDBADACBDBBDACACDBCADDACDAD AAAACBDDDCDBCDCDADDAADDBADADBCC ACCBBBBBBCCCBDBAADCDBBCACDDBDCD BDADCBCCAADCBBABDDADDACACBCABBA DABBCBADCACCBDBBDCDCBBDAAABDACA CABDDDAACADDADBABDAADBCABABCAAA DBDACAADCDDBDBBCDABBABACBBDBDCD BACABDBBCADDCBDBAADBBDCABCACACD CAABCDBCABDDACDACDAADABCCBBAABB BBCBBDABDDBCDADCDABCDAAACADADCD BDDDDCAABDBDBDAADCBBDBACCABCACC AACBCADCCBBBDCBBCDACCCCDCDACBCA CBBABBCDAABBCDBDDBDABACCBAADBAA BAADAACCDCDCADAADCBDBCCCCCDBCAA ABABABACDABCCBBDCADCDDCCBBAADDB ACBAABBBDAACCDACDDDDDCBADBDDDDD CCCDCABBDDCBCBBCDCBABACBBBDDBDD CABDDBADDDDADCCBACBCBDBBBDCCBBB ADCCBCDBBBAACDCDCBBDBADBDDCADBC ABCAADADDACCCCADDBDABBCCDCCCACA ABCBCBAADACBAABCBCCADBAAACBBCAA ADAADDDCCAAADABDDBADCDABDBCACAA ABCAAADDAACBCCADCBDBBCAACDBBACC BCAACBCABCBCCBCDADBACBDCDCCACCC ADDBBACBCABBCCDCDDCABCABBCCDAAD BAAABABCDCBDBBCDBDDBCADDDCBACDD ABCCBBBBDABCDADACBCADACBCCDDBBA ADACAADBBCDBAABACBDCDDDABABABBD DCAADBDBBCDBBDDBDBDDBBADCBDAABB 
BCCCAABBBAACDCDBCAABBBBCDDDCBDD CDDBAABBBDBCBABDCACDCAACDAABCAB BCCDCBBCCBDCCBDDDBCDADDCDABBADA BBBBBDCACCDBACDAADACBCCDBCBBDDB ADAABADCDADCDADAADDCCCABADDACAD DCBDBCBBCBCABAADDDABCDBCACBBDBB DBDAADBBDAACABDDAADBCDABBBADBAC CBADBCABCBBCBABBDCCACCDACDABCBB CDBDDBBCAABDAADABDAACABCBAABDDD AAADBBABDBDDACDDCDADCBACCBCBABD ABADCABCBDDDCADBDADCCACAADDBBDB BBACCCBBBCBCCDCBDBADBDDABDAACDD BCCDCBCACABCDABCDDDBABDABADBDDB DBDBDCDCBDCCACCAACDACCDAACBDABC DDDDCBCDDABDCCCBBDCACDAADCADBDD BCBBCDCDBDDDAACADBBADACCDCBDCCD BDBCBBBDDCDDCADDCABBBAAABCDBBDA DADCCDAACCDBBABAACBDADADDDDADDA BDCBCBDCCDABBCBACBBCBDCBBBABBDD ACCABABACCBBDDABDADCAACABCCCDCB DDBDDCADBCBACADDACAADCCCDDBAABA CBDBDCCDDBBCCCDCACBDBCBDACBABCC ACAABDBACADDACCCCDABADCDDBCAACA CCCBBBCBBCCAAABCADDBBAAAAABADDC DBAABBDBCAACBCDACADACCCCDBCABBC AAACBADCABCABAACBBDBADACABACADC DCCDDADDDBAADDCDCDABAABDBCACACC DADBCCBADDBBACBBADABCCBBADABBAC DDBDACACDBCBCCDCDDABCCBADABCCDA DCBBDDDABDDDCDBCBBBCABABDCBDABD BCBADBDDBBAAABBDDADDBDDADACDDBB 
AAAABBCAABAADAACBDBDBCACCAAABCB ACDCBDDACABCDBAADABBAACDAABBDCB DDADDDBBBBBBDCDDDCBCDBCDBBDCBCC ABBCDBACAACABCAAADAADDCADBACBCD DACCCABACBDCACCDCCBCDBDACADCDAD DAABDDABBCBADBCCCDBABACABACBBAC CDACDDCABCCDBCCACADDCBACBDACACB DCADACCDBBCCACAACCCBCCACADACDDB BBDDDBBCBCCBDAAADCBCDDDBADDDCBC CCACDCCDCBCDDDCDACABCAABBBBACAC BBCAACBAACDDADCCCDABCBBDCCABCDD ADDDDCBADABBBCDABABCBBBAAAADABA ABACAADBCCBDBBBAACCCADABBDDBABB ABDCDCDDDBCDCDCCABBABDACCCAACDD BBACBABCABBCBBBCDDADDDADACCDAAC BDDADCAADBDBADDACBADCDBBAADDADD BBACBABAACBCAAABCCABAAACDACDCBA ADCDABDCBABAADBDADCBDBCBABBABBA BBADBBDCCBBBBBDBBDCCACBBDACDBAA ACAADBABADBDABCCAABDBBDBBDCBDCC BCCCACDAAABDBBDACCDAABADCBCACCB ABACCBBCBBBABDACBDCAADCAABCABAB ADDCACDACDCBBAABACCAACCCADDBCCD CBDBCBDCDCDCDCABABADDDDBCDBBCDD ADCAAADBABDAABBBADDCCCCBDAABABA DBCBDDDBCCABCCAACDAAADCBDACBDAA ABCCCCAACACDBDCDADDBBBDDBCDAACD BBABDCCBCBCBBCDABDBBDBAAACBBBAB DCCDADBDCDBBBAAABCDAACDDBBAADCA CAADDDBCDACADDCADBDDADDBDDDBCCC ADBAAACBBDBBCDBDBCDCBBDCCCCDCCC 
CAAAACAABDBDDDCCBCCBCBACADBCABC CCABCACCABCCADACBBCACCADCDAACBA BCDABBDCCBCBBBCDCADACBCABCAABAB ABDCDDABDCDBBDCBABDABDBCCABCBDB CBCDBACADCADCCDCDBDAABCBCCABDAA ABACADDCBCABABBCBCAACDDBCCDCDCD DDDDBCDABCDACADDDACAAABDDBBAABB CDCDACBCBCDCDDBAADCCCCDDAAADACA BCBCDCCBBCCBBDDABBDCAABBCAAADAA AABADDBDACADBDDCCCBACCCDBCCABCC ABCDDDCADDDADCCDAAACBCDBDCADCDB CADCADDCABCBABDBCCBCBDCDCCDABCA CACDACCADDBADCBCCDABABCABBBCBDA DDDCDBADADDCABBBCCADADCACABAAAA CDABABBDCDDCAABAABAABDCCCBDCADC BACDDBCADCAACCADDCDDCDBDDBADCDC DCDADDABCABABACBDABCACBBBAADADD CBDBCABCCBCDBBDBCABDDAABAACCBCC BAACDBDDDDCCABBABDAACCCACACADAB CDBAADCBAABBCDBBDBDABBCDDDCCDCC CDCDAACBCBCCABCCDBCBCDABBAABDAC AABAABABAAADCAACACADABCCCDAABCB CACCACDDBCDCBDCCCBCBCACBBDABDCC CABAAACACABDACCCADBBDAADABABCCB DCDBBBABCCACABAAACDACBCDDDABBDB BCCABBDAACAACACDDCCBDACADAADDAC CBDCDCBACDDDDDACCAAABAABCBAABDB CCBBCABCDCDADBDBDCBDBACBBBCBBBC CAABACCADDDBDCABDAABACCCADADDAD DDDBACABCDCAAACAACDCDBDBADADCDB BDBAAAABDADDCBBADCCDBDCCDAACCCD 
CBADDCBBADAAABCBCAABBBDABDBBABD BADABABABAACBABBCCCADDCCBBACCAD ACBCCCDADBBABCDBCACDBBCACBABDDA BDDBACDBDCCABDDBABACCCCBCCAADDB BADDCABBBABACBBBACCACCCDCBABDCC BBBCCAAACBBACCBDADCAABBBAADCDAC DBBCCCDCABDBDBBCDAABCABAABADACA DBABBABDDACACDDAABBACBBDBABAACD CDAADABADBCCADADAACCCDDCADADDCD ABADCAABDCBCDADDDCCCCDDDBBBDDAD ABCBCBDCABCBACAABBBDBDAABBCAACD ACCBCCBBADDAABCBAACABDBBDDBBDBA DCBBDCDAACACACCBADADCABBCDADCCA DCBBBBADDCDCCDDBDBBDDACBDCDACCA AAABCCBADDDDDCCADADCDDDAABDBCAB ABCDABAADDBCDADACCBBDBDBABBCCBD BAADBAACCBDDCADDDAABCBDCDDADDCB DCABBCCBCDCBDBBDADDABBBDABDCDCD DBDDDAAAADAADBBADAACCCCDADBCCAC CDAABCADDADBBBDCABCCBABCBDBADAC ADCAACCABCDAACCCDBDCDADDADDBDAA CBCDBCBABCADBBBBABADBDCBADBDDCA BABADBCBBCCBDBACBAACDCCCABCCDAD DBDDCACCABDADABBBBACABADCBCDDDC ACACADDBABAABDBDADDCCDDDABBABBC ABBBCDDDCCABADBABBCCACACCDDDABC AAAAACACABDBDBDAABDBCBADABBAADB CACBABCABCACDDCBCDDCDDDCAABCBBC DCCBBACCDBDCBCCDDBCADBBCBBADDAD CBCBDDDCBBDDBCCADCCBCAADCCDACCA CDCBABCCDCCCCAADAABADCDCADADBBA 
ACBCCABBADAABDDACDCBCAABBCACDCC BCABCABBACDCCBCCBBCCCCADACCABAC CBDBBBACBCBDDABAAAABCDABBBDDDAA ABACAACCDAABDBBCACBCABACACAADAD DAABCCBDBADDBDABACDBACBDDCBBBAD BCBCDBCBBADCADBCDCBBADDBABCCCAA ADDCCDDAABBAADBBBDCADBBCADDADAA ACCCADBACCBDAABDCADBCAADDDCCBAA BCDABBDCADCDDBCABBADDCBABAADDAA BABCDDBDCCCAABADADCBBAACDDDDDAB AADCBDDBABCACBCCCDCADBABDCCABCB CABBDBDCCBDCDDCBCCBDDCACCDAADAD BADBCABABBBACCDBDDBCBBBCDBCCABD CBACDCDCCABCAADBAAAABDAADCDDABB ADBCABAABADADBBAABAACBBAADDCBBC ACDBACACDBADDACDACBACCDDBABAABA ADBDCDBAACBDCDDACAADDBBBADAADAC CDDBDDABCDACAAADBBACCCAABADBCCD BAADCDBADBDBBABDBDDADABBCAACDAC DCAACDACABBDAADDBCCACDDDBABCBAC BCBDBACBBDDDDDCCBBACABABDCAAACD CBCAACADBAABADABBDCBAADBACABABC DDACABCDBAACADDBDBABBDCBBDDBADB BCBCCCDCCADABDDABBADCAABDCBCBCC AADCCADDDADACBAAABAADBCBDACACBB DCACCCABAADBDCCDBCCCBCABADACADD CABDDCBDDDABAADAABBACBADAABCDDC BABADDDBDDABADDCACBBDCAABBCDAAD ABBAABDCAABCDCADABBCBCBACCDBCAB BABBDABDACCCDCBBADDDDBCBBBBCDDD CCCDDCBDADCBDDCBACADACCDAABCADA 
BCDDACBABACCABAABCDCCADAAABABBC DABBCBACBACDCCCCBAACCDDADCBBACB ADBCBCBCDDACCCBCCCACCCBDDACADCC ADBDDDDCDAAACAABDBDBBACBCABCDBA CDDBDBDBCBDCAACBDDADBABACBDACBA BBADADCDCDAACADBBDABCACDDCCBBBC AADDAAAACDABBCBDBABACBACDBADAAA DADBDBDCBDCBBCCBDDBBADAADDCBBBB DDCBCACBCACCDADDCBCBDDDBDDAADCD DABDABCBAACCDBBCBABBACCBADCBBDA DCDADCBCAAADBBDBBBDACAABCDDCADA CCCCAACCDACDBAAADCACBBCADCCAAAC CACDCDCABCDBDDABBDDAACAAABADCCB CDBACABCACBBACCACCABDACCDACBABC ABADCCDADDDAABDCBCADBDADBAAABAD CCACCDADAADCBCABBACBCDDBCCDCCAC DCDDDCDDACACDBBACADCBBBBBBDCDBA ACDBACACDCCCAAABADDCCCCBBBBDCBC BAACDBABDCCDCDBADADCDCAACAABCBB ACACBBBCDBADBCBACADBDADBBCDAACB ABBADBCABCDBBAAAACDBCBCDABDDBDC ADBADDCDBBABBACBBACCCABBBDCCCCB ADBDBABABAACCCBBAACCBBADACCAAAA AAAADCBBCDDBDDDCBBBDBBCCBCBCCDA DBABACDBBABBCCBAAAAADAACBCDBCCA ADBDCBBBDBBBCDAABBBACABDCDBCAAB BBAABDBAADABBDADAACDDBCBBCDADBA ACACBBBBDBDBCBBDBBBAADBCAACBCBA BDDAAABAACBDABABBADCACACBBDBBAA DBCABDDBBBAADBCDDADDCABDADCAABA BDABBABBCBDBBADAAAAABACBCABCBAB 
DBAAABBDCBDBDBBDDCBACDDABACCADB ADBBCAAADCBBACBCCCCDDDBABBACBCC CCDABADDCACDBACBABDADDCAAAACDBC DBCDDBBBAACBADBBBDDDCCCBBDABBBA AABDADCBBCBDBCDBCAADBCBACBCBDAD CBDDCABDDBDDBAADDDCBCDBDDBCBBAB DDABACAADDBBCCBBBCBBDDDADDABABA ACBBCBABABBBBBDCBCDBADBBACCCADA CCABDBCCDDBAACBAAAACADDADDCDACB BDCDCDACBCBDCBDCADDDBACCBCBBDCA ABAABBADBAABCBCCCABBCACBACABBBB BBACDBACABABCBBBDDDBAABCAADCAAC BACACADDDCACCCBCACBDACDDACBDDBC DAABACABCDCADCCCBADBDADACCDBCDD CCBADCDCCACDBBADBCDBDCCCABADCCA DCADBBAADCABBDCBBABCDABCCABBCBD BDCBBCDCADDAACBDDDDCDDADDACBACB ADDDCDABDCDCBDBBDCACABCABACCCAB ADCBAACBAAAADCBADACBABDBCCABBDC ADACDCCAAACCADDBBDAAAABCABACADD BBAABBCACDAABCBACCACAABABABDDCA AABBDCAABDCDCDBCCDCBABCDCBCCACC CCBAACDBAAAACCDCDDACCBCADDDACAA AACCCADABCCADBCCCBCBBABBCBAADBA ADDCDDBDAACDBDADBCDCBDBDCCDDCAB DDCDBDCBAADBCCADBABBCAACBDBBAAD CACBBAAACACCBAAACBBDDBCBDBBAADC CCDBBDACDDBCCBAACABBADBABADCADB BCABAACDCBCCCDCDBADAABACBABDDDC BAADDDDBCBDAADCDDDBCBBCDDCDCAAD ACACBDDCAAAACADDDAADCABBBDADACC 
ABBADDDAACDBACDDABDBCACCABDDDBA AABCCDAABACDADCBACADDABCDBBBBCD ACABDBBCDCBCDCADDCCBDCAABCDDCBC BDBAACCBCBDABBABDDADCCBDACBCCAA AAAAADDBBCAAADADADDBDACDDABBADC ADDBBDBDBCDBADAAACDCCCBADBCAABB CAADDACBCABBCACBCDDBBABABADCCBC DABCDADDAAAADDCBDAADCCCBDCDDCBB BDADDBCCBACBCBCACDDABCCCCACCCAC BABACACDCDABBABAAACAABAAABADCCC CADCBADCAABADBCCAADDDBDCBBDDCAA BBBACCBCACCCDDAAACACBBDACBAAABA DCBCCCCDBBBAAABDBDACABCBADDBBCD DADCBDDACADDACBBBBAABABCACBDDAC CDAAADDBCBBBADCCCACBDBBADDABBBD DCCDBBACCCDBBBBBBBCADBDCAAAABDA ADDBAAADCADABBACCDCDBDBDCDBDCAA DDCABBDDDDAAAAABDAADDBBADAABCAC CCCDADDCCDBBCDCADDACBDAABDBACBA DBDDDBBABBCBDDACACCBDDBADCBBCAB DCDBADCAAABADCBABAACAACDCBBDBCC CADDCCCACDDDBAABBCDDCADDDBCDCAA CADCABCACBCDBDDBCBDBADBBCABABDC DDADDABACDABBDCACBCBBADDBCDDCCC BCABACDCCADDBBACBCADADCACBCDCCC BBADACCCADBBCCACDBDAACABAAADBBA ADBBCACADDCBBCDABBACCADBCADCABA ABCABCDDCCCBCABDDACDBADCADAABDC BCDBBBDCCDDBCBDBCCDCACCBABABBAC DBBCABCDBCBDBDDCDCACBCDBDBDBABC ADDACBCBABCDABDADDABDDCDBDACABB 
BCBDDCBBBDDCCDCCDAABDDDCACDCAAD DDD-BDA-CBD-BDB-BDD-ADC-CBC-AAB ADD-CDD-CCB-CCB-DDB-ACC-ABA-BCB ------------------------------- B-AAC-ACA-BCD-DCB-CAC-BAA-BAB-D D-DAC-CDD-CCD-BAD-ABD-CBB-ADC-A ------------------------------- DBA-BAD-DAC-ACB-BDD-DAA-DCD-ACD ADB-DDA-CBC-BCD-BCD-BAB-DBD-CDC ------------------------------- C-ACD-BCC-BDB-ABD-DBA-DCD-DBC-D A-ADA-CDA-ACA-CAC-DDB-ADB-ABD-A ------------------------------- DBD-ACA-BBA-CAC-DBD-ABB-ABC-ACA AAC-CBA-DBC-DCD-CCC-BDA-AAC-DDC ------------------------------- B-BCA-ACD-ABD-BAC-ADA-DCC-ABB-D A-CCB-BCD-BCD-CDD-CCC-BAB-DAC-C ------------------------------- BAC-DDC-ADB-BBD-BDC-BCC-DCA-DAD DDB-CCA-BAC-ACA-ADB-DDD-CDD-ACC ------------------------------- C-ADA-BAC-CDA-CDB-ADC-ADB-CCA-B C-CDD-ABA-BAC-DDD-ACD-ADB-CCC-D ------------------------------- DCC-BAA-ACD-DCB-CAD-DCB-DBA-CBB DCD-ADD-DCC-ABD-CCC-AAD-AAA-ABA BADACADACCBCBBDBDDABBACACAADDBA CCDAABCCAAADCABCDACBBCCADADBDAC DCDCABDBBCDDDABCBADABABABCABCBD DAAADBBCBABDBCCDBCDBCCBDADCDADA 
BDCDACCACABBCABDBABCBABADDDCBCD ------------------------------- ------------------------------- ------------------------------- ------------------------------- ------------------------------- ------------------------------- ------------------------------- ------------------------------- ------------------------------- ------------------------------- ------------------------------- ------------------------------- ------------------------------- ------------------------------- ------------------------------- ------------------------------- ------------------------------- ------------------------------- ------------------------------- ------------------------------- ------------------------------- ------------------------------- ------------------------------- ------------------------------- ------------------------------- ------------------------------- CABCDCADAADBDBABCCDBBBBABCBBBDD CAAADCCBCDDABBCDADCABDABABDDBAB ADADDDBBACDDABCDDCCAAAABACADCBC CADADCCBDDACBCAABBBCABCBDBCADAC 
------------------------------- ------------------------------- ------------------------------- ------------------------------- ------------------------------- ------------------------------- ------------------------------- ------------------------------- ------------------------------- ------------------------------- ------------------------------- ------------------------------- ------------------------------- ------------------------------- ------------------------------- ------------------------------- ------------------------------- ------------------------------- ------------------------------- ------------------------------- ------------------------------- ------------------------------- ------------------------------- ------------------------------- ------------------------------- ------------------------------- ------------------------------- ------------------------------- BBBDADBAABDBCADBDCDBCADABCCBCCC DDDACDAADDCAADCCCABABCDDABCABCA BCADBDCAACADCDDDAACBAABDCBDAADA 
------------------------------- ------------------------------- ------------------------------- ------------------------------- ------------------------------- ------------------------------- ------------------------------- ------------------------------- ------------------------------- ------------------------------- ------------------------------- ------------------------------- ------------------------------- ------------------------------- ------------------------------- ------------------------------- ------------------------------- ------------------------------- ------------------------------- ------------------------------- ------------------------------- ------------------------------- ------------------------------- ------------------------------- ------------------------------- ------------------------------- ------------------------------- ------------------------------- ------------------------------- CABBBADCDADCCABDCBCCADADADCABDD ADCBDBDCDCCABBADAADBDBCBCCCACBC 
------------------------------- ------------------------------- ------------------------------- ------------------------------- ------------------------------- ------------------------------- ------------------------------- ------------------------------- ------------------------------- ------------------------------- ------------------------------- ------------------------------- ------------------------------- ------------------------------- ------------------------------- ------------------------------- ------------------------------- ------------------------------- ------------------------------- ------------------------------- ------------------------------- ------------------------------- ------------------------------- ------------------------------- ------------------------------- ------------------------------- ------------------------------- ------------------------------- ------------------------------- ------------------------------- CBDADADDBDAAADBDAAADDACACAACCDC 
