model
name = -6-floor_smooth_var1
size = 31 6 31
scale = 0.05
origin = -y
shell = Outline 0.25
material type = toon, lighting = smooth, deform = 1 1
  colors = A:#5A5A5A B:#353535 C:#4B4B4B D:#555 E:#242424
material type = basic, lighting = smooth, roughness = 0, refractionRatio = 1, side = back
  colors = Outline:#000
voxels
ABADCDABBDBABBBBDCEBAACCADACDCD CAACDBBBCDBACBDBBEEACCDAACBBADB ACACADAAABDADACDEEAACCABBBACADA BDACAACDAAADBABCEDCADBACDCDDACB AABBDCBADCDCABBEEADABDCBABCBCCA EEEEEEEEEEEEEEEEEEEEEEEEEEEEEEE 
DBADBACDCCABBCDDADCDDDBBCBCABBA ABBBBCACCCADDCBBCBCAACACBBAACCD DBBACDDDCCDBBCADAADBADABBADCDCD ACDCCDCBADCCACDCADCADDCACDDDBDB BDBCBCDBBCACCCBDACDACACBABCCBDD ECDDDACBCBADDCEEACDDAADBBBCAABE 
DAABDCBCBABDCDCDBCCDAABDDCDBABA BADDDBADADDBDAADACCDADADDDBCDCA ADCBADBBBADCCCCBCDACBBBDBDABBDB ABACAADAAADCDBDBAABCABDCACBAADC DCABADCDCACCCACBCBCCDBCBBDCAABD EABCBCDAAADDCEECACCDDCBDCDBDBBE 
CACBAAACBACCCAADCABCBAABACDCBBC BBDCDADBCADACAAADCADADACBDCCAAB DACDAAADADACDAACBAACCBBCCABABBD DBDBDBCDDBDDAACCAAAAAACDDBACCAB CBADCDAADABCCBAAADAADBAAACDDDAB EBBCAABCDCDEEEABCDACDADCDCAACCE 
ABBBADABCBCAACADCCACACBBCADADBA ADDAADCABACCCBBDACBDDBCBADBADAD ACCCCDCBABDABDDCDCBCBDADCACADAC ACAADDADACACABABDBCBDADDBAAACDD DBCADCAADDAADACDBAAABDADCDDBCCB EDCCBCBBAAEEEAACADCABBCBCBCCACE 
ABDDADADBBBADBDDCBCDCCCACACBDDB DCADBDADDAACBBBBCDCCCABCCCBDABC CDBAACBDACABDDBACDABCBABDADBCDA CDADCCCCBCBBCBBBBADACDCDDCCDCAB DAABACDABCBDDBDCBBAAACCCCBCABCA EBACBADAEEABEEBBADBBADCACDDDDDE 
CAABBDAAACBCDBDACCCCCCBCCCCDBCA ACADABDCDDDDDCBCACCBABBAABDAACD ABDDCACDBDABDCAABDDCCBAABACBBBA BDAACDBDBBBDBACADABBCCDBDDABCCA BCBBDBDACACCCDDADADDBACCBBBCBCC EBDCDCEEEBADDEEAADCBADABADBDDBE 
DCCAABBBACCDDDBDDCBBDBDDACDBABB BBCBBCDCABCBABCACDACBDADCDDAACA AAABADABADDCBBBDCBAACCAABCDDCAB DBCCBBCCCBCDDCAADBBABCCCDCCCAAD DDCBACBDBDDACDADDABABDDCDCCCDCB EDBBEEEDBCCCCBEEABDDCDDBCDCDDAE 
ADCAAAAACCDCABACDBBDCABCDDBDDCC CABCBCBBBBDDCBABABBBCABBCDCBDAB BBDDADBBAAAABCABBADAACBCCCBABAC DDBCDDCDDBBCBADAABDACAADACDDCAB CCDBABCDABADDDBDCDCBCBADDBBBBDD EEEEEEAADBBBDBCEEBCAACDCCCAADDE 
BDADCCBBBBDDBBAAADDADAABACCCACB ABCBABDAABBACACDAACCDCBBCCDCDCA ACBACDACAADDADAADACACDAABCBADAB ECACDCCDDBCBCADBBDCDCAABAABDADC EACBADCAABCCCBBBBCDBBADDCDAACDC ECAACEAAADAAAAAAEEABCBBDABACCDE 
DAABDCBDDBBBDBDDACABBACACCBDABD ADAADBABCCBAADDCACBBCCDBABBBBAD EDCAADCACDAADDABBADCACBBDBDDBDC EDDDBCABCCBCADDCCBCACDCBBDDBABA DDBDBBAACDBBDCBBAABCDCBBABCCACD ECCAABEBCADBDCCCAEEECCBBBBCAABE 
BAABBCCDBBDBADCCDBACCABDDCACDCD ECBBBCDCBDBDACADCDCDBACDCBDCDAA EBACBBCCCDADCBCCBCCCCCCCAABDCCD ADCCCCCBBBBABCBABCBACDDCCABBACA ADACDCBAADCCBACCCCCDADDDBADCDCA EBDDADECBDACADDBBBEEEEBAACCDBEE 
ECBDDDADCABBBDCCBCACABCACDDCBDA EADADDCACCCBABCBCACBBDDDCDABADB BBABBDAAADBBABCCDCCCBDDBDBCACDC ADBCDBCBBDDCAADAAAABDCDDDDAABCA ADBBBDCABDDACADACDDDCCAAADBBDAE EBCADBEBCAAABABDCABDAAEEEEEEEEE 
CDBBDDABCBAADABDACDADCBBBDBDDBB BAABCBDBDBDBCCACDABCCDDDCCABBBD CDBDDBABAAABACCAACADCBBCCDABBAD BCACABABCDDCDDDCBBACCCDDDCBBDBE DDBBBCCBAABAACCBADDBBCACACADDAE EBDDACEABAADAADBCBDDBEEBADBCADE 
BDACDBCBAABBCDAABCBDCAABADDDBDA AAAACCDDDABDAAABBBCABDCDBCDCAAA BCABDBBCDCBADCBBABBADAAACAAACBE DCCBADACBADCDDAAAADBBDDDABADBAE BBBADCBBAABDBDBDCBDDDCCBABCDCAA ECABCCEBCACCDAAADCBEEEBCACDDBAE 
CCABDCBDAABCBADBBDDBADDCDDCCBCD CDADBCBADABBADCDBBAAADBDBDBDBCE CACBDCBCACDAACBABCBCDAABBCBBDBE CABADBCDDADACDDACCBCBADBACAADBB BDDADCBBAACAACCAADDDABBCCACBABA EDDDDBECDCADABDBDCEEACADDCDAABE 
AADDCAAACBABADCDDAACABBDBDAABAE DDBCADACCBBDCCDBAADAABABCBDCACE ABCCADCACBBDACBBDCCACBBACBDDDAA DAACABBCDADDCDACAAADADBBBBDCDCB AACCAABACBAACAACACBCCBDBBDADCAC EBABCCECBABBAAABAEEABAADACBDBDE 
CCDCCAABABACCCABACCDBDACCDDAAAE DBBBCCDBABACCABCACDCBADDCAAAADC DCDABBCDACCCCBDBACACDAABDBDABAA DBDAACBDDCCADDDDBBBCDBCDAAADBCD CBCAACADAADCABDDCADABDBAADDABCA EACDCDEBCBAAAABBEEDBBBCDCCDBDAE 
DCCCBAAAAACCBDBAAACABAADAABCADA BABDCBDDCBCDABACBCCBABDADBCADCB DBBBCDBBDBDBCAAABBBADBADCBDBADB CDBCBBADBABDDABADCACBCCCADBCBDD CCACACCCCBDDDBCABBACDBDDBBBDBDA EBABDDEDBCDCDCAEEBBADBABCABCADE 
BABADDDCACBDADDBDABABBBAACBCADC BDADDCBBBBBDDBDBBBBCADBBAAABABD BACBABBADDACABCCBAAADDCDADCBABA CCADDABDDADCBBCBDDBBBCCACAAAAAD BABBBBCBAADDBBDBBADACBCDDABBDBC EDCCDEBCDBAABCEEECDACADCBCDABCE 
BABABADCAAADCADCDBACADBDBCCDCCA ADADDCBAABDBBDDDDABDCDCBBAAACBA BCBCCDCDDBACBBBCDDCCCABADACDDAB ACBBCBDCBDBABDDDCADCCACDCDBCADA BABDCACCAACDCCBAADAACBBABACBDDA EACCDEEEDCBAEEEBEEDACDABBDCDDBE 
CCDDAACBBBCCADDDDCDDDABADBAABAC DACADDBADADCCCDDDBCDCDDBCCCDCCB CBCABBDBABDAADABBADBAACDBDBCBAB ADAAAAACCDDACBADAADDBBACABBADBA BDACCBCCCBCCDDCBBCBCABCCBDCBACA ECBAAEDEEAEEEAADBEEBBADDADABBBE 
ACCDBABDBDBDADAADCCACBDBBDDBCDB ABCADCBADCCCCBBCBBBCADDBCBDCBBA DACCDAADAADABCBBDDACDBAADBCCADD ABBCCCBDBCDCACADAAADBBCADBCAACD DBBABADDCDCDBBAACCCABACCBAADADA ECBBECCCEEECADDBCAEECCACACBBACE 
DCCDCBCAADBBDDBBBCCCDADCBAAABAD ACDACCADDCAADCADAADCDDBCBBDDBAA AAACCCDACAADABBCCDBDABBACADACBA BBCCDADCDDDBDBBAAABCBCAACBABDBA DCDBBBDBDDDDBBDBBBCAACBDABCBDCD EDCDEBCAEECBAABADAAEEADACABCABE 
ADBDAACBCAABAACCAADCDBAAABDCCDB ACBDDADDDBCBABDBBCBCBBBADDDAADA DDCAACCDBBBDCBADDBBDDADDACDCADD ADDDCBCAABBABAADCBCCBDACCACBDAD DBBCCDDCDDBCDCCABBAAACDBACCCBDB EDDEEBBBCECCBCDCBDCBEECCBCDABAE 
ECABDACABCCBCCACDBBCDBABDBDCDBB EABBABDABDBDCDCCBCBBBCBCBCDCBDB DDABDCCBAABCCABBBDBDDCCACCCBBDC DADBBBCCBADDBACDBAAABDDCDDBDABA CDBBCDBADCCCADCABCCCBCAADABCAAD EDBEBCDABEEACBCACACADEEDDDDDADE 
ACCDCABCBADBACDBCDCAABBBCADDAAA EAADABBACDABDBAAADCABDDBCDCBABD ECCCADCBCDDDBDADADBDACCBCDAAADA EABDDCCCABCCABCBADCDADDBADADDBB CADABBBBDDBCBDBBBCDAAABADADABCA EAEEEABABDEACAACACACAAEEECBDCBE 
CCCACACBCDCDBABDADADDCDBACDBAAB ADBACADBBCABCCBADBBCAAAABDABDCC BBBCBBBCABDBCCCABBADBBADDBABDBB EDBCCBBACBACADADCDDCBBDDBBBACBC EBCBCAADCADABBDACAACACCDCABDDCB EEEABBADCCEEADBCDBDCDCDCEEADCDE 
AADCDBCDDDCBDCAABCBDCBCCADBCDCC BACAACBBADABCACBCCCDABBDAABDBDB CCCAACAAADDACABDACCDBBAADDACACC DDCDBCAADABCDABCADABCCBADABDABC CDDADCAABABCABBDBBBCACACBAABBBB EDAAADAADABEDCDAADDDDCBABEECBDE 
CABDBBCAABBACDABBACDAADDDBDDBCB AABDADAADDDBCDCABBCBBDCDBAAABBB CBBCBCCCCCCAADBABDBCCAACBDDBADB DCCACBBBDCBBCBCABCBDBCDBBCADBDA DADCBAACBDDCBDABDCBBAABCDAACBBB EDACCDCBAACAEBDBDADDCAAADBEEBBE 
CCDCDACCBABCBDDECBADDBBDCACCECD AABDADCBDBAAAAEEDCBDACBABABEECD BDCBACCDCCAAADEDBACDCCCBAACECDC DAADBABBCCDCBCEDBDDCAABABACECDC ADCCABABBCAAAEBABBDBDBDABCDECAD EEEEEEEEEEEEEEEEEEEEEEEEEEEEEEE 
