model
name = -7-floor_smooth_var2
revision = 3
size = 31 6 31
scale = 0.05
origin = -y
shell = Outline 0.25
material type = toon, lighting = smooth, deform = 1 1
  colors = A:#5A5A5A B:#353535 D:#555 C:#4B4B4B E:#242424 F:#C52707
material type = basic, lighting = smooth, roughness = 0, refractionRatio = 1, side = back
  colors = Outline:#000
voxels
ABADCDABBDBABBBBDCEEAACCADACDCD CAACDBBBCDBACBDBEEEACCDAACBBADB ACACADAAABDADACEEAAACCABBBACADA BDACAACDAAADBABEDDCADBACDCDDACB AABBDCBADCDCABBECADABDCBABCBCCA EEEEEEEEEEEEEEEEEEEEEEEEEEEEEEE 
DBADBACDCCABBCDDADCDDDBBCBCABBA ABBBBCACCCADDCBBCBCAACACBBAACCD DBBACDDDCCDBBCADAADBADABBADCDCD ACDCCDCBADCCACDCADCADDCACDDDBDB BDBCBCDBBCACCCBDACDACACBABCCBDD ECDDDACBCBADDEEDACDDAADBBBCAABE 
DAABDCBCBABDCDCDBCCDAABDDCDBABA BADDDBADADDBDAADACCDADADDDBCDCA ADCBADBBBADCCCCBCDACBBBDBDABBDB ABACAADAAADCDBDBAABCABDCACBAADC DCABADCDCACCCACBCBCCDBCBBDCAABD EABCBCDAAADDCAECACCDDCBDCDBDBBE 
CACBAAACBACCCAADCABCBAABACDCBBC BBDCDADBCADACAAADCADADACBDCCAAB DACDAAADADACDAACBAACCBBCCABABBD DBDBDBCDDBDDAACCAAAAAACDDBACCAB CBADCDAADABCCBAAADAADBAAACDDDAB EBBCAABCDCDBACEBCDACDADCDCAACCE 
EBBBADABCBCAACADCCACACBBCADADBA ADDAADCABACCCBBDACBDDBCBADBADAD ACCCCDCBABDABDDCDCBCBDADCACADAC ACAADDADACACABABDBCBDADDBAAACDD DBCADCAADDAADACDBAAABDADCDDBCCB EDCCBCBBAACAAAEEADCABBCBCBCCACE 
EBDDADADBBBADBDDCBCDCCCACACBDDB ECADBDADDAACBBBBCDCCCABCCCBDABC CDBAACBDACABDDBACDABCBABDADBCDA CDADCCCCBCBBCBBBBADACDCDDCCDCAB DAABACDABCBDDBDCBBAAACCCCBCABCA EBACBADABBABBDBEEEBBADCACDDDDDE 
CAABBDAAACBCDBDACCCCCCBCCCCDBCA ECADABDCDDDDDCBCACCBABBAABDAACD EBDDCACDBDABDCAABDDCCBAABACBBBA EDAACDBDBBBDBACADABBCCDBDDABCCA BCBBDBDACACCCDDADADDBACCBBBCBCC EBDCDCCBBBADDDCAAEEBADABADBDDBE 
DCCAABBBACCDDDBDDCBBDBDDACDBABB BBCBBCDCABCBABCACDACBDADCDDAACA AAABADABADDCBBBDCBAACCAABCDDCAB EBCCBBCCCBCDDCAADBBABCCCDCCCAAD EDCBACBDBDDACDADDABABDDCDCCCDCB EDBBCBBDBCCCCBABABEECDDBCDCDDAE 
ADCAAAAACCDCABACDBBDCABCDDBDDCC CABCBCBBBBDDCBABABBBCABBCDCBDAB BBDDADBBAAAABCABBADAACBCCCBABAC DDBCDDCDDBBCBADAABDACAADACDDCAB ECDBABCDABADDDBDCDCBCBADDBBBBDD EECADDAADBBBDBCACBCAEEECCCAADDE 
BDADCCBBBBDDBBAAADDADAABACCCACE ABCBABDAABBACACDAACCDCBBCCDCDCE ACBACDACAADDADAADACACDAABCBADAB DCACDCCDDBCBCADBBDCDCAABAABDADC AACBADCAABCCCBBBBCDBBADDCDAACDC EEEACBAAADAAAAAADBABCEEEEBACCDE 
DAABDCBDDBBBDBDDACABBACACCBDABD ADAADBABCCBAADDCACBBCCDBABBBBAE ADCAADCACDAADDABBADCACBBDBDDBDE BDDDBCABCCBCADDCCBCACDCBBDDBABA DDBDBBAACDBBDCBBAABCDCBBABCCACD ECEEABBBCADBDCCCADDCCEBEEECAABE 
BAABBCCDBBDBADCCDBACCABDDCACDCD DCBBBCDCBDBDACADCDCDBACDCBDCDAA BBACBBCCCDADCBCCBCCCCCCCAABDCCE ADCCCCCBBBBABCBABCBACDDCCABBACE ADACDCBAADCCBACCCCCDADDDBADCDCA EBDDEDCCBDACADDBBBAAEEBAAEEDBCE 
CCBDDDADCABBBDCCBCACABCACDDCBDA DADADDCACCCBABCBCACBBDDDCDABADB BBABBDAAADBBABCCDCCCBDDBDBCACDC ADBCDBCBBDDCAADAAAABDCDDDDAABCE ADBBBDCABDDACADACDDDCCAAADBBDAE EBCAEEBBCAAABABDCABDEABDDBDEEAE 
CDBBDDABCBAADABDACDADCBBBDBDDBB BAABCBDBDBDBCCACDABCCDDDCCABBBD CDBDDBABAAABACCAACADCBBCCDABBAD BCACABABCDDCDDDCBBACCCDDDCBBDBD DDBBBCCBAABAACCBADDBBCACACADDAE EBDDAEAABAADAADBCBDEEADBADBCEEE 
BDACDBCBAABBCDAABCBDCAABADDDBDA AAAACCDDDABDAAABBBCABDCDBCDCAAA BCABDBBCDCBADCBBABBADAAACAAACBC DCCBADACBADCDDAAAADBBDDDABADBAB BBBADCBBAABDBDBDCBDDDCCBABCDCAA ECABCEEBCACCDAAADCEEDABCACDDBAE 
CCABDCBDAABCBADBBDDBADDCDDCCBCD CDADBCBADABBADCDBBAAADBDBDBDBCC CACBDCBCACDAACBABCBCDAABBCBBDBC CABADBCDDADACDDACCBCBADBACAADBB BDDADCBBAACAACCAADDDABBCCACBABA EDDDDBECDCADABDBDEEDACADDCDAABE 
AADDCAAACBABADCDDAACABBDBDAABAA DDBCADACCBBDCCDBAADAABABCBDCACD ABCCADCACBBDACBBDCCACBBACBDDDAA DAACABBCDADDCDACAAADADBBBBDCDCB AACCAABACBAACAACACBCCBDBBDADCAC EBABCCEEBABBAAABEEAABAADACBDBDE 
CCDCCAABABACCCABACCDBDACCDDAAAD DBBBCCDBABACCABCACDCBADDCAAAADC DCDABBCDACCCCBDBACACDAABDBDABAA DBDAACBDDCCADDDDBBBCDBCDAAADBCD CBCAACADAADCABDDCADABDBAADDABCA EACDCDBECBAAAABEEDDBBBCDCCDBDAE 
DCCCBAAAAACCBDBAAACABAADAABCADA BABDCBDDCBCDABACBCCBABDADBCADCB DBBBCDBBDBDBCAAABBBADBADCBDBADB CDBCBBADBABDDABADCACBCCCADBCBDD CCACACCCCBDDDBCABBACDBDDBBBDBDA EBABDDBEECDCDCEEDBBADBABCABCADE 
BABADDDCACBDADDBDABABBBAACBCADC BDADDCBBBBBDDBDBBBBCADBBAAABABD BACBABBADDACABCCBAAADDCDADCBABA CCADDABDDADCBBCBDDBBBCCACAAAAAD BABBBBCBAADDBBDBBADACBCDDABBDBC EDCCDCBCEBAABEECEEEACADCBCDABCE 
BABABADCAAADCADCDBACADBDBCCDCCA ADADDCBAABDBBDDDDABDCDCBBAAACBA BCBCCDCDDBACBBBCDDCCCABADACDDAB ACBBCBDCBDBABDDDCADCCACDCDBCADA BABDCACCAACDCCBAADAACBBABACBDDA EACCDBDDEEBEEBB--------BBDCDDBE 
CCDDAACBBBCCADDDDCDDDABADBAABAC DACADDBADADCCCDDDBCDCDDBCCCDCCB CBCABBDBABDAADABBADBAACDBDBCBAB ADAAAAACCDDACBADAADDBBACABBADBA BDACCBCCCBCCDDCBBCBCABCCBDCBACA ECBAACDBEEEABAAFFFFFF--DADABBBE 
ACCDBABDBDBDADAADCCACBDBBDDBCDB ABCADCBADCCCCBBCBBBCADDBCBDCBBA DACCDAADAADABCBBDDACDBAADBCCADD ABBCCCBDBCDCACADAAADBBCADBCAACD DBBABADDCDCDBBAACCCABACCBAADADA ECBBBCEECCCCADDFFFFFF--CACBBACE 
DCCDCBCAADBBDDBBBCCCDADCBAAABAD ACDACCADDCAADCADAADCDDBCBBDDBAA AAACCCDACAADABBCCDBDABBACADACBA BBCCDADCDDDBDBBAAABCBCAACBABDBA DCDBBBDBDDDDBBDBBBCAACBDABCBDCD EDCDBEEACACBAABFFFFFF--ACABCABE 
ADBDAACBCAABAACCAADCDBAAABDCCDB ACBDDADDDBCBABDBBCBCBBBADDDAADA DDCAACCDBBBDCBADDBBDDADDACDCADD ADDDCBCAABBABAADCBCCBDACCACBDAD DBBCCDDCDDBCDCCABBAAACDBACCCBDB EDDAEEBBCACCBCDFFFFFF--EBCDABAE 
DCABDACABCCBCCACDBBCDBABDBDCDBB AABBABDABDBDCDCCBCBBBCBCBCDCBDB DDABDCCBAABCCABBBDBDDCCACCCBBDC DADBBBCCBADDBACDBAAABDDCDDBDABA CDBBCDBADCCCADCABCCCBCAADABCAAD EDBEECDABABACBC--------EEDDDADE 
ACCDCABCBADBACDBCDCAABBBCADDAAA CAADABBACDABDBAAADCABDDBCDCBABD CCCCADCBCDDDBDADADBDACCBCDAAADA DABDDCCCABCCABCBADCDADDBADADDBB CADABBBBDDBCBDBBBCDAAABADADABCA EEEEDABABDCACAA--------AEEBDCBE 
CCCACACBCDCDBABDADADDCDBACDBAAB ADBACADBBCABCCBADBBCAAAABDABDCC BBBCBBBCABDBCCCABBADBBADDBABDBB DDBCCBBACBACADADCDDCBBDDBBBACBC EBCBCAADCADABBDACAACACCDCABDDCE EEAABBADCCCAADBCDBDCDCDCDEEEEEE 
AADCDBCDDDCBDCAABCBDCBCCADBCDCC BACAACBBADABCACBCCCDABBDAABDBDB CCCAACAAADDACABDACCDBBAADDACACC EDCDBCAADABCDABCADABCCBADABDABE EDDADCAABABCABBDBBBCACACBAABBBE EDAAADAADABADCDAADDDDCBABADCBDE 
CABDBBCAABBACDABBACDAADDDBDDBCB AABDADAADDDBCDCABBCBBDCDBAAABBB EBBCBCCCCCCAADBABDBCCAACBDDBADE ECCACBBBDCBBCBCABCBDBCDBBCADBDE DADCBAACBDDCBDABDCBBAABCDAACBBB EDACCDCBAACADBDBDADDCAAADBCDBBE 
CCDCDACCBABCBDDACBADDBBDCACCEEE EABDADCBDBAAAABADCBDACBABABDACE EDCBACCDCCAAADADBACDCCCBAACBCDE DAADBABBCCDCBCCDBDDCAABABACACDC ADCCABABBCAAAABABBDBDBDABCDACAD EEEEEEEEEEEEEEEEEEEEEEEEEEEEEEE 
