model
name = -7-floor_smooth_var2
size = 31 6 31
scale = 0.05
origin = -y
material type = toon, lighting = smooth, deform = 1 1 
  colors = A:#5A5A5A B:#353535 C:#4B4B4B D:#555 E:#242424
voxels
ABADCDABBDBABBBBDCEEAACCADACDCD CAACDBBBCDBACBDBEEEACCDAACBBADB ACACADAAABDADACEEAAACCABBBACADA BDACAACDAAADBABEDDCADBACDCDDACB AABBDCBADCDCABBECADABDCBABCBCCA EEEEEEEEEEEEEEEEEEEEEEEEEEEEEEE 
DBADBACDCCABBCDDADCDDDBBCBCABBA ABBBBCACCCADDCBBCBCAACACBBAACCD DBBACDDDCCDBBCADAADBADABBADCDCD ACDCCDCBADCCACDCADCADDCACDDDBDB BDBCBCDBBCACCCBDACDACACBABCCBDD ECDDDACBCBADDEEDACDDAADBBBCAABE 
DAABDCBCBABDCDCDBCCDAABDDCDBABA BADDDBADADDBDAADACCDADADDDBCDCA ADCBADBBBADCCCCBCDACBBBDBDABBDB ABACAADAAADCDBDBAABCABDCACBAADC DCABADCDCACCCACBCBCCDBCBBDCAABD EABCBCDAAADDCAECACCDDCBDCDBDBBE 
CACBAAACBACCCAADCABCBAABACDCBBC BBDCDADBCADACAAADCADADACBDCCAAB DACDAAADADACDAACBAACCBBCCABABBD DBDBDBCDDBDDAACCAAAAAACDDBACCAB CBADCDAADABCCBAAADAADBAAACDDDAB EBBCAABCDCDBACEBCDACDADCDCAACCE 
EBBBADABCBCAACADCCACACBBCADADBA ADDAADCABACCCBBDACBDDBCBADBADAD ACCCCDCBABDABDDCDCBCBDADCACADAC ACAADDADACACABABDBCBDADDBAAACDD DBCADCAADDAADACDBAAABDADCDDBCCB EDCCBCBBAACAAAEEADCABBCBCBCCACE 
EBDDADADBBBADBDDCBCDCCCACACBDDB ECADBDADDAACBBBBCDCCCABCCCBDABC CDBAACBDACABDDBACDABCBABDADBCDA CDADCCCCBCBBCBBBBADACDCDDCCDCAB DAABACDABCBDDBDCBBAAACCCCBCABCA EBACBADABBABBDBEEEBBADCACDDDDDE 
CAABBDAAACBCDBDACCCCCCBCCCCDBCA ECADABDCDDDDDCBCACCBABBAABDAACD EBDDCACDBDABDCAABDDCCBAABACBBBA EDAACDBDBBBDBACADABBCCDBDDABCCA BCBBDBDACACCCDDADADDBACCBBBCBCC EBDCDCCBBBADDDCAAEEBADABADBDDBE 
DCCAABBBACCDDDBDDCBBDBDDACDBABB BBCBBCDCABCBABCACDACBDADCDDAACA AAABADABADDCBBBDCBAACCAABCDDCAB EBCCBBCCCBCDDCAADBBABCCCDCCCAAD EDCBACBDBDDACDADDABABDDCDCCCDCB EDBBCBBDBCCCCBABABEECDDBCDCDDAE 
ADCAAAAACCDCABACDBBDCABCDDBDDCC CABCBCBBBBDDCBABABBBCABBCDCBDAB BBDDADBBAAAABCABBADAACBCCCBABAC DDBCDDCDDBBCBADAABDACAADACDDCAB ECDBABCDABADDDBDCDCBCBADDBBBBDD EECADDAADBBBDBCACBCAEEECCCAADDE 
BDADCCBBBBDDBBAAADDADAABACCCACE ABCBABDAABBACACDAACCDCBBCCDCDCE ACBACDACAADDADAADACACDAABCBADAB DCACDCCDDBCBCADBBDCDCAABAABDADC AACBADCAABCCCBBBBCDBBADDCDAACDC EEEACBAAADAAAAAADBABCEEEEBACCDE 
DAABDCBDDBBBDBDDACABBACACCBDABD ADAADBABCCBAADDCACBBCCDBABBBBAE ADCAADCACDAADDABBADCACBBDBDDBDE BDDDBCABCCBCADDCCBCACDCBBDDBABA DDBDBBAACDBBDCBBAABCDCBBABCCACD ECEEABBBCADBDCCCADDCCEBEEECAABE 
BAABBCCDBBDBADCCDBACCABDDCACDCD DCBBBCDCBDBDACADCDCDBACDCBDCDAA BBACBBCCCDADCBCCBCCCCCCCAABDCCE ADCCCCCBBBBABCBABCBACDDCCABBACE ADACDCBAADCCBACCCCCDADDDBADCDCA EBDDEDCCBDACADDBBBAAEEBAAEEDBCE 
CCBDDDADCABBBDCCBCACABCACDDCBDA DADADDCACCCBABCBCACBBDDDCDABADB BBABBDAAADBBABCCDCCCBDDBDBCACDC ADBCDBCBBDDCAADAAAABDCDDDDAABCE ADBBBDCABDDACADACDDDCCAAADBBDAE EBCAEEBBCAAABABDCABDEABDDBDEEAE 
CDBBDDABCBAADABDACDADCBBBDBDDBB BAABCBDBDBDBCCACDABCCDDDCCABBBD CDBDDBABAAABACCAACADCBBCCDABBAD BCACABABCDDCDDDCBBACCCDDDCBBDBD DDBBBCCBAABAACCBADDBBCACACADDAE EBDDAEAABAADAADBCBDEEADBADBCEEE 
BDACDBCBAABBCDAABCBDCAABADDDBDA AAAACCDDDABDAAABBBCABDCDBCDCAAA BCABDBBCDCBADCBBABBADAAACAAACBC DCCBADACBADCDDAAAADBBDDDABADBAB BBBADCBBAABDBDBDCBDDDCCBABCDCAA ECABCEEBCACCDAAADCEEDABCACDDBAE 
CCABDCBDAABCBADBBDDBADDCDDCCBCD CDADBCBADABBADCDBBAAADBDBDBDBCC CACBDCBCACDAACBABCBCDAABBCBBDBC CABADBCDDADACDDACCBCBADBACAADBB BDDADCBBAACAACCAADDDABBCCACBABA EDDDDBECDCADABDBDEEDACADDCDAABE 
AADDCAAACBABADCDDAACABBDBDAABAA DDBCADACCBBDCCDBAADAABABCBDCACD ABCCADCACBBDACBBDCCACBBACBDDDAA DAACABBCDADDCDACAAADADBBBBDCDCB AACCAABACBAACAACACBCCBDBBDADCAC EBABCCEEBABBAAABEEAABAADACBDBDE 
CCDCCAABABACCCABACCDBDACCDDAAAD DBBBCCDBABACCABCACDCBADDCAAAADC DCDABBCDACCCCBDBACACDAABDBDABAA DBDAACBDDCCADDDDBBBCDBCDAAADBCD CBCAACADAADCABDDCADABDBAADDABCA EACDCDBECBAAAABEEDDBBBCDCCDBDAE 
DCCCBAAAAACCBDBAAACABAADAABCADA BABDCBDDCBCDABACBCCBABDADBCADCB DBBBCDBBDBDBCAAABBBADBADCBDBADB CDBCBBADBABDDABADCACBCCCADBCBDD CCACACCCCBDDDBCABBACDBDDBBBDBDA EBABDDBEECDCDCEEDBBADBABCABCADE 
BABADDDCACBDADDBDABABBBAACBCADC BDADDCBBBBBDDBDBBBBCADBBAAABABD BACBABBADDACABCCBAAADDCDADCBABA CCADDABDDADCBBCBDDBBBCCACAAAAAD BABBBBCBAADDBBDBBADACBCDDABBDBC EDCCDCBCEBAABEECEEEACADCBCDABCE 
BABABADCAAADCADCDBACADBDBCCDCCA ADADDCBAABDBBDDDDABDCDCBBAAACBA BCBCCDCDDBACBBBCDDCCCABADACDDAB ACBBCBDCBDBABDDDCADCCACDCDBCADA BABDCACCAACDCCBAADAACBBABACBDDA EACCDBDDEEBEEBBBCDEECDABBDCDDBE 
CCDDAACBBBCCADDDDCDDDABADBAABAC DACADDBADADCCCDDDBCDCDDBCCCDCCB CBCABBDBABDAADABBADBAACDBDBCBAB ADAAAAACCDDACBADAADDBBACABBADBA BDACCBCCCBCCDDCBBCBCABCCBDCBACA ECBAACDBEEEABAADBDBEEADDADABBBE 
ACCDBABDBDBDADAADCCACBDBBDDBCDB ABCADCBADCCCCBBCBBBCADDBCBDCBBA DACCDAADAADABCBBDDACDBAADBCCADD ABBCCCBDBCDCACADAAADBBCADBCAACD DBBABADDCDCDBBAACCCABACCBAADADA ECBBBCEECCCCADDBCAABCEACACBBACE 
DCCDCBCAADBBDDBBBCCCDADCBAAABAD ACDACCADDCAADCADAADCDDBCBBDDBAA AAACCCDACAADABBCCDBDABBACADACBA BBCCDADCDDDBDBBAAABCBCAACBABDBA DCDBBBDBDDDDBBDBBBCAACBDABCBDCD EDCDBEEACACBAABADAADCAEACABCABE 
ADBDAACBCAABAACCAADCDBAAABDCCDB ACBDDADDDBCBABDBBCBCBBBADDDAADA DDCAACCDBBBDCBADDBBDDADDACDCADD ADDDCBCAABBABAADCBCCBDACCACBDAD DBBCCDDCDDBCDCCABBAAACDBACCCBDB EDDAEEBBCACCBCDCBDCBABEEBCDABAE 
DCABDACABCCBCCACDBBCDBABDBDCDBB AABBABDABDBDCDCCBCBBBCBCBCDCBDB DDABDCCBAABCCABBBDBDDCCACCCBBDC DADBBBCCBADDBACDBAAABDDCDDBDABA CDBBCDBADCCCADCABCCCBCAADABCAAD EDBEECDABABACBCACACADDCEEDDDADE 
ACCDCABCBADBACDBCDCAABBBCADDAAA CAADABBACDABDBAAADCABDDBCDCBABD CCCCADCBCDDDBDADADBDACCBCDAAADA DABDDCCCABCCABCBADCDADDBADADDBB CADABBBBDDBCBDBBBCDAAABADADABCA EEEEDABABDCACAACACACAADAEEBDCBE 
CCCACACBCDCDBABDADADDCDBACDBAAB ADBACADBBCABCCBADBBCAAAABDABDCC BBBCBBBCABDBCCCABBADBBADDBABDBB DDBCCBBACBACADADCDDCBBDDBBBACBC EBCBCAADCADABBDACAACACCDCABDDCE EEAABBADCCCAADBCDBDCDCDCDEEEEEE 
AADCDBCDDDCBDCAABCBDCBCCADBCDCC BACAACBBADABCACBCCCDABBDAABDBDB CCCAACAAADDACABDACCDBBAADDACACC EDCDBCAADABCDABCADABCCBADABDABE EDDADCAABABCABBDBBBCACACBAABBBE EDAAADAADABADCDAADDDDCBABADCBDE 
CABDBBCAABBACDABBACDAADDDBDDBCB AABDADAADDDBCDCABBCBBDCDBAAABBB EBBCBCCCCCCAADBABDBCCAACBDDBADE ECCACBBBDCBBCBCABCBDBCDBBCADBDE DADCBAACBDDCBDABDCBBAABCDAACBBB EDACCDCBAACADBDBDADDCAAADBCDBBE 
CCDCDACCBABCBDDACBADDBBDCACCEEE EABDADCBDBAAAABADCBDACBABABDACE EDCBACCDCCAAADADBACDCCCBAACBCDE DAADBABBCCDCBCCDBDDCAABABACACDC ADCCABABBCAAAABABBDBDBDABCDACAD EEEEEEEEEEEEEEEEEEEEEEEEEEEEEEE 
