model
name = Apple
revision = 1
size = 20 40 20
origin = -y
shell = Outline 0.25
material type = toon, lighting = smooth, deform = 1 1
  colors = B:#620042
material type = basic, lighting = smooth, roughness = 0, refractionRatio = 1, side = back
  colors = Outline:#000
voxels
380-366B13-7B14-5B395-349B2(7-10B13-7B14-5B395-339B-9B)2(7-10B2(13-7B)13-B380-258B3(2-18B)2-19B-9B)7-13B7-11B13-7B393-258B3(2-18B)2-19B-9B7-13B7-11B13-7B393-219B-19B-4(18B2-)19B-9B7-13B7-B2-8B13-7B393-219B-19B-4(18B2-)29B7-13B7-B2-2(8B13-7B393-219B3(-19B)-93B6-)8B13-7B393-355B5-8B12-7B13-4B396-259B2(-19B)-55B5-8B12-7B13-4B396-259B3(-19B)-17B3-15B5-8B12-7B13-7B393-259B3(-19B)-17B3-15B5-13B7-7B13-6B394-355B5-13B7-7B13-6B394-367B3-2B7-8B13-6B394-367B3-2B2-13B13-7B393-372B2-3B3-7B13-7B393-387B13-7B13-
