model
name = Apple
revision = 8404
size = 20 40 21
origin = -y
shell = Outline 0.25
material type = toon, lighting = smooth, deform = 1 1
  colors = B:#620042
material type = basic, lighting = smooth, roughness = 0, refractionRatio = 1, side = back
  colors = Outline:#000
voxels
1180-3(366B13-7B13-6B14-B380-)2(366B2(13-7B)13-B380-)2(420B380-)6(408B10-2B380-)6(420B380-)420B
