model
name = Ducky
revision = 8406
size = 20 40 20
origin = -y
shell = Outline 0.25
material type = toon, lighting = smooth, deform = 1 1
  colors = B:#620042
material type = basic, lighting = smooth, roughness = 0, refractionRatio = 1, side = back
  colors = Outline:#000
voxels
10(380-420B)380-299B2(-19B)-80B3(380-420B)380-5B9(10-10B)10-225B5(380-5B9(10-10B)15-5(11B9-)120B)
