model
name = Ducky
revision = 8412
size = 20 40 20
origin = -y
shell = Outline 0.25
material type = toon, lighting = smooth, deform = 1 1
  colors = B:#620042
material type = basic, lighting = smooth, roughness = 0, refractionRatio = 1, side = back
  colors = Outline:#000
voxels
10(380-420B)380-4B10(12-8B)12-83B2(-19B)-80B2(380-4B10(12-8B)12-204B)2(380-5B10(11-9B)11-204B)5(380-5B9(11-9B)15-5B15-4(11B9-)120B)
