model
name = Ducky
revision = 8431
size = 20 40 30
origin = -y
shell = Outline 0.25
material type = toon, lighting = smooth, deform = 1 1
  colors = B:#620042 C:#AD1D07
material type = basic, lighting = smooth, roughness = 0, refractionRatio = 1, side = back
  colors = Outline:#000
voxels
4380-3B2(12-8B)7(12-4BC3B)12-4B2(11(C19B)C380-3B2(13-7B)7(13-3BC3B)13-3B)11(C19B)2(C380-2B2(14-6B)8(14-3BC2B)10(12-5BC2B)12-5B)3(C380-2B2(13-7B)8(13-4BC2B)10(12-5BC2B)12-5B)C380-2B2(13-7B)8(13-4BC2B)4(12-5BC2B)12-5B-6(2B12-5BC)380-2B2(13-7B)8(13-4BC2B)10(12-5BC2B)11-6BC380-2B2(14-6B)9(14-3BC2B)3(12-5BC2B)3(12-5B-2B)3(12-5BC2B)11-6BC380-2B2(14-6B)9(14-3BC2B)9(12-5BC2B)11-6BC380-2B11(14-6B)6(12-8B)3(12-5BC2B)11-6BC380-2B11(14-6B)6(12-8B)12-5BC2B12-5B-2B12-5BC2B11-6BC380-2B11(14-6B)5(12-8B)12-5BC2B3(12-8B)5(11-7B380-2B9(14-6B)6(18-2B)5(12-8B))11-7B4000-
