model
name = Ducky
revision = 8427
size = 20 40 30
origin = -y
shell = Outline 0.25
material type = toon, lighting = smooth, deform = 1 1
  colors = B:#620042
material type = basic, lighting = smooth, roughness = 0, refractionRatio = 1, side = back
  colors = Outline:#000
voxels
4380-3B9(12-8B)12-225B2(380-3B9(13-7B)13-224B)2(380-2B10(14-6B)10(12-8B)12-6B)3(380-2B10(13-7B)10(12-8B)12-6B)380-2B10(13-7B)4(12-8B)12-5B-2B5(12-8B)12-6B380-2B10(13-7B)10(12-8B)11-7B380-2B11(14-6B)3(12-8B)3(12-5B-2B)3(12-8B)4(11-7B380-2B11(14-6B)9(12-8B))5(11-7B380-2B9(14-6B)6(18-2B)5(12-8B))11-7B4000-
