model
name = Ducky
revision = 4
size = 20 40 20
origin = -y
shell = Outline 0.25
material type = toon, lighting = smooth, deform = 1 1
  colors = B:#AD1D07 C:#C52707
material type = basic, lighting = smooth, roughness = 0, refractionRatio = 1, side = back
  colors = Outline:#000
voxels
380-3B9(12-8B)12-165B2C2(15B5C)15B3C2(380-3B9(13-7B)13-224B)380-2B10(14-6B)6(12-8B)4(12-5BC2B)12-6B380-2B10(14-6B)5(12-8B)5(12-5BC2B)3(12-6B380-2B10(13-7B)5(12-8B)2(12-5BC2B)3(12-8B))12-6B380-2B10(13-7B)4(12-8B)12-5B-2B5(12-8B)12-6B380-2B10(13-7B)10(12-8B)11-7B380-2B11(14-6B)3(12-8B)3(12-5B-2B)3(3(12-8B)11-7B380-2B11(14-6B)4(12-8B)2(12-5BC2B))12-8B12-5B-2B12-8B11-7B380-2B11(14-6B)4(12-8B)5(12-5BC2B)11-7B380-2B9(14-6B)6(18-2B)12-8B4(12-5BC2B)2(11-7B380-2B9(14-6B)6(18-2B)5(12-8B))11-7B2(380-2B9(14-6B)6(18-2B)2(12-8B)12-6B2C2(12-3B5C)11-4B3C)
