model
name = Ducky
revision = 8439
size = 20 40 30
origin = -y
shell = Outline 0.25
material type = toon, lighting = smooth, deform = 1 1
  colors = C:#AD1D07 B:#620042
material type = basic, lighting = smooth, roughness = 0, refractionRatio = 1, side = back
  colors = Outline:#000
voxels
4380-3C8(12-B7C)12-B4C3B12-4B4(C19B)141C2(380-3C9(13-7C)13-224C)2(380-2C10(14-6C)10(12-8C)12-6C)3(380-2C10(13-7C)10(12-8C)12-6C)380-2C10(13-7C)4(12-8C)12-5C-2C5(12-8C)12-6C380-2C10(13-7C)10(12-8C)11-7C380-2C11(14-6C)3(12-8C)3(12-5C-2C)3(12-8C)2(11-7C380-2C11(14-6C)9(12-8C))11-7C380-2C11(14-6C)7(12-8C)12-5C-2C12-8C11-7C380-2C11(14-6C)9(12-8C)3(11-7C380-2C9(14-6C)6(18-2C)5(12-8C))2(11-7C380-2C8(14-6C)14-4C5(2B18-)2C18-2C5(12-8C))11-7C4000-
