model
name = Hello
revision = 8412
size = 20 40 20
origin = -y
shell = Outline 0.25
material type = toon, lighting = smooth, deform = 1 1
  colors = B:#C52707
material type = basic, lighting = smooth, roughness = 0, refractionRatio = 1, side = back
  colors = Outline:#000
voxels
380-380B420-370B-9B420-370B9-B420-339B-38B422-319B3(-19B)421-339B-19B-20B420-133B2(-20B-19B)-19B-20B2(-19B)2-B-2(17B3-)16B4-16B3-B420-113B-16B12(10-10B)430-114B-15B2(10-10B)10-2(9B11-)7(10B10-)10B430-114B-15B3(10-10B)10-2(9B11-)6(10B10-)10B430-115B-14B5(10-10B)10-9B11-5(10B10-)10B430-115B2-13B6(10-10B)10-9B11-4(10B10-)7B433-116B2-12B7(10-10B)10-2(9B11-)2(10B10-)9B431-117B-12B8(10-10B)10-3(9B11-)9B431-117B-12B6(10-10B)10-3(9B11-)2(10B10-)10B430-110B-6B-12B6(10-10B)10-5(9B11-)8B432-116B2-11B11-7(10B10-)9B11-3(10B10-)9B431-112B3-15B7(10-10B)10-9B11-3(10B10-)10B430-130B12(10-10B)430-155B2(4-16B)4-15B5-15B6-6(11B9-)11B49-
