model
name = Voxy
revision = 8430
size = 24 40 22
origin = -y
shell = Outline 0.25
material type = toon, lighting = smooth, deform = 1 1
  colors = B:#C52707
material type = basic, lighting = smooth, roughness = 0, refractionRatio = 1, side = back
  colors = Outline:#000
voxels
1418-5(20B4-)19B5-14(20B4-)20B460-5(20B4-)19B5-12(20B4-)21B3-20B4-20B460-2(5(20B4-)19B5-11(20B4-)3(21B3-)21B459-)17(20B4-)2(3(21B3-)21B459-5(20B4-)20B268-)2(20B4-2(21B3-)21B459-5(20B4-)20B268-)20B4-2(21B3-)20B460-5(20B4-)20B268-2(20B4-2(21B3-)20B460-20B4-4(19B5-)19B269-)20B4-2(21B3-)21B459-20B4-4(19B5-)19B269-2(20B4-)21B3-2(21B459-20B4-4(19B5-)19B269-20B4-2(21B3-))21B459-20B4-10(19B5-)8(20B4-)19B5-20B460-20B4-10(19B5-)20B4-3(21B3-)2(20B4-)19B5-18B6-19B5-19B461-20B4-10(19B5-)20B4-21B3-22B2-21B3-2(20B4-)19B5-17B7-18B6-19B461-12(20B4-)3(21B3-)2(20B4-)19B5-18B6-17B7-19B461-17(20B4-)3(19B5-)19B715-B247-
