model
name = Voxy
revision = 8427
size = 22 40 21
origin = -y
shell = Outline 0.25
material type = toon, lighting = smooth, deform = 1 1
  colors = B:#C52707
material type = basic, lighting = smooth, roughness = 0, refractionRatio = 1, side = back
  colors = Outline:#000
voxels
1299-5(20B2-)19B3-14(20B2-)20B420-5(20B2-)19B3-12(20B2-)21B-20B2-20B420-2(5(20B2-)19B3-11(20B2-)3(21B-)21B419-)17(20B2-)2(3(21B-)21B419-5(20B2-)20B244-)2(20B2-2(21B-)21B419-5(20B2-)20B244-)20B2-2(21B-)20B420-5(20B2-)20B244-2(20B2-2(21B-)20B420-20B2-4(19B3-)19B245-)20B2-2(21B-)21B419-20B2-4(19B3-)19B245-2(20B2-)21B-2(21B419-20B2-4(19B3-)19B245-20B2-2(21B-))21B419-20B2-10(19B3-)8(20B2-)19B3-20B420-20B2-10(19B3-)6(20B2-)19B3-18B4-19B3-19B421-20B2-10(19B3-)6(20B2-)19B3-17B5-18B4-19B421-17(20B2-)19B3-18B4-17B5-19B421-17(20B2-)3(19B3-)19B2-
